Error in Gemini report generation: 'AIReportGeneratorAdapter' object has no attribute 'openai_generator'
Traceback (most recent call last):
  File "C:\Users\MSii\Desktop\Threat-Detection-and-Notification-Platform-by-Analyzing-Logs-of-Apache-and-MySQL-servers-\ai_analytics\services.py", line 637, in generate_report
    cached_report = self.openai_generator._check_cache(report_type, start_time, end_time,
                    ^^^^^^^^^^^^^^^^^^^^^
AttributeError: 'AIReportGeneratorAdapter' object has no attribute 'openai_generator'. Did you mean: 'gemini_generator'?
Report generation failed: No report object returned
Internal Server Error: /ai/reports/generate/
Error in Gemini report generation: 'AIReportGeneratorAdapter' object has no attribute 'openai_generator'
Traceback (most recent call last):
  File "C:\Users\MSii\Desktop\Threat-Detection-and-Notification-Platform-by-Analyzing-Logs-of-Apache-and-MySQL-servers-\ai_analytics\services.py", line 637, in generate_report
    cached_report = self.openai_generator._check_cache(report_type, start_time, end_time,
                    ^^^^^^^^^^^^^^^^^^^^^
AttributeError: 'AIReportGeneratorAdapter' object has no attribute 'openai_generator'. Did you mean: 'gemini_generator'?
Report generation failed: No report object returned
Internal Server Error: /ai/reports/generate/
Error in Gemini report generation: 'AIReportGeneratorAdapter' object has no attribute 'openai_generator'
Traceback (most recent call last):
  File "C:\Users\MSii\Desktop\Threat-Detection-and-Notification-Platform-by-Analyzing-Logs-of-Apache-and-MySQL-servers-\ai_analytics\services.py", line 636, in generate_report
    cached_report = self.openai_generator._check_cache(report_type, start_time, end_time,
                    ^^^^^^^^^^^^^^^^^^^^^
AttributeError: 'AIReportGeneratorAdapter' object has no attribute 'openai_generator'. Did you mean: 'gemini_generator'?
Report generation failed: No report object returned
Internal Server Error: /ai/reports/generate/
Error in Gemini report generation: 'AIReportGeneratorAdapter' object has no attribute 'openai_generator'
Traceback (most recent call last):
  File "C:\Users\MSii\Desktop\Threat-Detection-and-Notification-Platform-by-Analyzing-Logs-of-Apache-and-MySQL-servers-\ai_analytics\services.py", line 636, in generate_report
    cached_report = self.openai_generator._check_cache(report_type, start_time, end_time,
                    ^^^^^^^^^^^^^^^^^^^^^
AttributeError: 'AIReportGeneratorAdapter' object has no attribute 'openai_generator'. Did you mean: 'gemini_generator'?
Report generation failed: No report object returned
Internal Server Error: /ai/reports/generate/
Error in Gemini report generation: 'AIReportGeneratorAdapter' object has no attribute 'openai_generator'
Traceback (most recent call last):
  File "C:\Users\MSii\Desktop\Threat-Detection-and-Notification-Platform-by-Analyzing-Logs-of-Apache-and-MySQL-servers-\ai_analytics\services.py", line 636, in generate_report
    cached_report = self.openai_generator._check_cache(report_type, start_time, end_time,
                    ^^^^^^^^^^^^^^^^^^^^^
AttributeError: 'AIReportGeneratorAdapter' object has no attribute 'openai_generator'. Did you mean: 'gemini_generator'?
Report generation failed: No report object returned
Internal Server Error: /ai/reports/generate/
Error in Gemini report generation: 'AIReportGeneratorAdapter' object has no attribute 'openai_generator'
Traceback (most recent call last):
  File "C:\Users\MSii\Desktop\Threat-Detection-and-Notification-Platform-by-Analyzing-Logs-of-Apache-and-MySQL-servers-\ai_analytics\services.py", line 636, in generate_report
    cached_report = self.openai_generator._check_cache(report_type, start_time, end_time,
                    ^^^^^^^^^^^^^^^^^^^^^
AttributeError: 'AIReportGeneratorAdapter' object has no attribute 'openai_generator'. Did you mean: 'gemini_generator'?
Report generation failed: No report object returned
Internal Server Error: /ai/reports/generate/
Error in Gemini report generation: 'AIReportGeneratorAdapter' object has no attribute 'openai_generator'
Traceback (most recent call last):
  File "C:\Users\MSii\Desktop\Threat-Detection-and-Notification-Platform-by-Analyzing-Logs-of-Apache-and-MySQL-servers-\ai_analytics\services.py", line 636, in generate_report
    cached_report = self.openai_generator._check_cache(report_type, start_time, end_time,
                    ^^^^^^^^^^^^^^^^^^^^^
AttributeError: 'AIReportGeneratorAdapter' object has no attribute 'openai_generator'. Did you mean: 'gemini_generator'?
Report generation failed: No report object returned
Internal Server Error: /ai/reports/generate/
Error in Gemini report generation: 'AIReportGeneratorAdapter' object has no attribute 'openai_generator'
Traceback (most recent call last):
  File "C:\Users\MSii\Desktop\Threat-Detection-and-Notification-Platform-by-Analyzing-Logs-of-Apache-and-MySQL-servers-\ai_analytics\services.py", line 636, in generate_report
    cached_report = self.openai_generator._check_cache(report_type, start_time, end_time,
                    ^^^^^^^^^^^^^^^^^^^^^
AttributeError: 'AIReportGeneratorAdapter' object has no attribute 'openai_generator'. Did you mean: 'gemini_generator'?
Report generation failed: No report object returned
Internal Server Error: /ai/reports/generate/
Error in Gemini report generation: 'AIReportGeneratorAdapter' object has no attribute 'openai_generator'
Traceback (most recent call last):
  File "C:\Users\MSii\Desktop\Threat-Detection-and-Notification-Platform-by-Analyzing-Logs-of-Apache-and-MySQL-servers-\ai_analytics\services.py", line 636, in generate_report
    cached_report = self.openai_generator._check_cache(report_type, start_time, end_time,
                    ^^^^^^^^^^^^^^^^^^^^^
AttributeError: 'AIReportGeneratorAdapter' object has no attribute 'openai_generator'. Did you mean: 'gemini_generator'?
Report generation failed: No report object returned
Internal Server Error: /ai/reports/generate/
Date parsing error: strptime() argument 1 must be str, not None
Date parsing error: strptime() argument 1 must be str, not None
Date parsing error: strptime() argument 1 must be str, not None
Date parsing error: strptime() argument 1 must be str, not None
Date parsing error: strptime() argument 1 must be str, not None
Date parsing error: strptime() argument 1 must be str, not None
Date parsing error: strptime() argument 1 must be str, not None
Error extracting data for report: name 'MysqlLogEntry' is not defined
Traceback (most recent call last):
  File "C:\Users\MSii\Desktop\Threat-Detection-and-Notification-Platform-by-Analyzing-Logs-of-Apache-and-MySQL-servers-\ai_analytics\services.py", line 374, in _extract_data_for_time_period
    mysql_logs = MysqlLogEntry.objects.filter(mysql_filter).order_by('-timestamp')[:100]
                 ^^^^^^^^^^^^^
NameError: name 'MysqlLogEntry' is not defined. Did you mean: 'MySQLLogEntry'?
Error in report_detail: (1054, "Unknown column 'ai_analytics_aireportfeedback.created_at' in 'SELECT'")
Traceback (most recent call last):
  File "C:\Users\MSii\Desktop\Threat-Detection-and-Notification-Platform-by-Analyzing-Logs-of-Apache-and-MySQL-servers-\Venv\Lib\site-packages\django\db\backends\utils.py", line 105, in _execute
    return self.cursor.execute(sql, params)
           ~~~~~~~~~~~~~~~~~~~^^^^^^^^^^^^^
  File "C:\Users\MSii\Desktop\Threat-Detection-and-Notification-Platform-by-Analyzing-Logs-of-Apache-and-MySQL-servers-\Venv\Lib\site-packages\django\db\backends\mysql\base.py", line 76, in execute
    return self.cursor.execute(query, args)
           ~~~~~~~~~~~~~~~~~~~^^^^^^^^^^^^^
  File "C:\Users\MSii\Desktop\Threat-Detection-and-Notification-Platform-by-Analyzing-Logs-of-Apache-and-MySQL-servers-\Venv\Lib\site-packages\MySQLdb\cursors.py", line 179, in execute
    res = self._query(mogrified_query)
  File "C:\Users\MSii\Desktop\Threat-Detection-and-Notification-Platform-by-Analyzing-Logs-of-Apache-and-MySQL-servers-\Venv\Lib\site-packages\MySQLdb\cursors.py", line 330, in _query
    db.query(q)
    ~~~~~~~~^^^
  File "C:\Users\MSii\Desktop\Threat-Detection-and-Notification-Platform-by-Analyzing-Logs-of-Apache-and-MySQL-servers-\Venv\Lib\site-packages\MySQLdb\connections.py", line 280, in query
    _mysql.connection.query(self, query)
    ~~~~~~~~~~~~~~~~~~~~~~~^^^^^^^^^^^^^
MySQLdb.OperationalError: (1054, "Unknown column 'ai_analytics_aireportfeedback.created_at' in 'SELECT'")

The above exception was the direct cause of the following exception:

Traceback (most recent call last):
  File "C:\Users\MSii\Desktop\Threat-Detection-and-Notification-Platform-by-Analyzing-Logs-of-Apache-and-MySQL-servers-\ai_analytics\views.py", line 76, in report_detail
    user_feedback = AIReportFeedback.objects.filter(report=report, user=request.user).first()
  File "C:\Users\MSii\Desktop\Threat-Detection-and-Notification-Platform-by-Analyzing-Logs-of-Apache-and-MySQL-servers-\Venv\Lib\site-packages\django\db\models\query.py", line 1097, in first
    for obj in queryset[:1]:
               ~~~~~~~~^^^^
  File "C:\Users\MSii\Desktop\Threat-Detection-and-Notification-Platform-by-Analyzing-Logs-of-Apache-and-MySQL-servers-\Venv\Lib\site-packages\django\db\models\query.py", line 400, in __iter__
    self._fetch_all()
    ~~~~~~~~~~~~~~~^^
  File "C:\Users\MSii\Desktop\Threat-Detection-and-Notification-Platform-by-Analyzing-Logs-of-Apache-and-MySQL-servers-\Venv\Lib\site-packages\django\db\models\query.py", line 1928, in _fetch_all
    self._result_cache = list(self._iterable_class(self))
                         ~~~~^^^^^^^^^^^^^^^^^^^^^^^^^^^^
  File "C:\Users\MSii\Desktop\Threat-Detection-and-Notification-Platform-by-Analyzing-Logs-of-Apache-and-MySQL-servers-\Venv\Lib\site-packages\django\db\models\query.py", line 91, in __iter__
    results = compiler.execute_sql(
        chunked_fetch=self.chunked_fetch, chunk_size=self.chunk_size
    )
  File "C:\Users\MSii\Desktop\Threat-Detection-and-Notification-Platform-by-Analyzing-Logs-of-Apache-and-MySQL-servers-\Venv\Lib\site-packages\django\db\models\sql\compiler.py", line 1574, in execute_sql
    cursor.execute(sql, params)
    ~~~~~~~~~~~~~~^^^^^^^^^^^^^
  File "C:\Users\MSii\Desktop\Threat-Detection-and-Notification-Platform-by-Analyzing-Logs-of-Apache-and-MySQL-servers-\Venv\Lib\site-packages\django\db\backends\utils.py", line 122, in execute
    return super().execute(sql, params)
           ~~~~~~~~~~~~~~~^^^^^^^^^^^^^
  File "C:\Users\MSii\Desktop\Threat-Detection-and-Notification-Platform-by-Analyzing-Logs-of-Apache-and-MySQL-servers-\Venv\Lib\site-packages\django\db\backends\utils.py", line 79, in execute
    return self._execute_with_wrappers(
           ~~~~~~~~~~~~~~~~~~~~~~~~~~~^
        sql, params, many=False, executor=self._execute
        ^^^^^^^^^^^^^^^^^^^^^^^^^^^^^^^^^^^^^^^^^^^^^^^
    )
    ^
  File "C:\Users\MSii\Desktop\Threat-Detection-and-Notification-Platform-by-Analyzing-Logs-of-Apache-and-MySQL-servers-\Venv\Lib\site-packages\django\db\backends\utils.py", line 92, in _execute_with_wrappers
    return executor(sql, params, many, context)
  File "C:\Users\MSii\Desktop\Threat-Detection-and-Notification-Platform-by-Analyzing-Logs-of-Apache-and-MySQL-servers-\Venv\Lib\site-packages\django\db\backends\utils.py", line 100, in _execute
    with self.db.wrap_database_errors:
         ^^^^^^^^^^^^^^^^^^^^^^^^^^^^
  File "C:\Users\MSii\Desktop\Threat-Detection-and-Notification-Platform-by-Analyzing-Logs-of-Apache-and-MySQL-servers-\Venv\Lib\site-packages\django\db\utils.py", line 91, in __exit__
    raise dj_exc_value.with_traceback(traceback) from exc_value
  File "C:\Users\MSii\Desktop\Threat-Detection-and-Notification-Platform-by-Analyzing-Logs-of-Apache-and-MySQL-servers-\Venv\Lib\site-packages\django\db\backends\utils.py", line 105, in _execute
    return self.cursor.execute(sql, params)
           ~~~~~~~~~~~~~~~~~~~^^^^^^^^^^^^^
  File "C:\Users\MSii\Desktop\Threat-Detection-and-Notification-Platform-by-Analyzing-Logs-of-Apache-and-MySQL-servers-\Venv\Lib\site-packages\django\db\backends\mysql\base.py", line 76, in execute
    return self.cursor.execute(query, args)
           ~~~~~~~~~~~~~~~~~~~^^^^^^^^^^^^^
  File "C:\Users\MSii\Desktop\Threat-Detection-and-Notification-Platform-by-Analyzing-Logs-of-Apache-and-MySQL-servers-\Venv\Lib\site-packages\MySQLdb\cursors.py", line 179, in execute
    res = self._query(mogrified_query)
  File "C:\Users\MSii\Desktop\Threat-Detection-and-Notification-Platform-by-Analyzing-Logs-of-Apache-and-MySQL-servers-\Venv\Lib\site-packages\MySQLdb\cursors.py", line 330, in _query
    db.query(q)
    ~~~~~~~~^^^
  File "C:\Users\MSii\Desktop\Threat-Detection-and-Notification-Platform-by-Analyzing-Logs-of-Apache-and-MySQL-servers-\Venv\Lib\site-packages\MySQLdb\connections.py", line 280, in query
    _mysql.connection.query(self, query)
    ~~~~~~~~~~~~~~~~~~~~~~~^^^^^^^^^^^^^
django.db.utils.OperationalError: (1054, "Unknown column 'ai_analytics_aireportfeedback.created_at' in 'SELECT'")
Error in report_detail: (1054, "Unknown column 'ai_analytics_aireportfeedback.created_at' in 'SELECT'")
Traceback (most recent call last):
  File "C:\Users\MSii\Desktop\Threat-Detection-and-Notification-Platform-by-Analyzing-Logs-of-Apache-and-MySQL-servers-\Venv\Lib\site-packages\django\db\backends\utils.py", line 105, in _execute
    return self.cursor.execute(sql, params)
           ~~~~~~~~~~~~~~~~~~~^^^^^^^^^^^^^
  File "C:\Users\MSii\Desktop\Threat-Detection-and-Notification-Platform-by-Analyzing-Logs-of-Apache-and-MySQL-servers-\Venv\Lib\site-packages\django\db\backends\mysql\base.py", line 76, in execute
    return self.cursor.execute(query, args)
           ~~~~~~~~~~~~~~~~~~~^^^^^^^^^^^^^
  File "C:\Users\MSii\Desktop\Threat-Detection-and-Notification-Platform-by-Analyzing-Logs-of-Apache-and-MySQL-servers-\Venv\Lib\site-packages\MySQLdb\cursors.py", line 179, in execute
    res = self._query(mogrified_query)
  File "C:\Users\MSii\Desktop\Threat-Detection-and-Notification-Platform-by-Analyzing-Logs-of-Apache-and-MySQL-servers-\Venv\Lib\site-packages\MySQLdb\cursors.py", line 330, in _query
    db.query(q)
    ~~~~~~~~^^^
  File "C:\Users\MSii\Desktop\Threat-Detection-and-Notification-Platform-by-Analyzing-Logs-of-Apache-and-MySQL-servers-\Venv\Lib\site-packages\MySQLdb\connections.py", line 280, in query
    _mysql.connection.query(self, query)
    ~~~~~~~~~~~~~~~~~~~~~~~^^^^^^^^^^^^^
MySQLdb.OperationalError: (1054, "Unknown column 'ai_analytics_aireportfeedback.created_at' in 'SELECT'")

The above exception was the direct cause of the following exception:

Traceback (most recent call last):
  File "C:\Users\MSii\Desktop\Threat-Detection-and-Notification-Platform-by-Analyzing-Logs-of-Apache-and-MySQL-servers-\ai_analytics\views.py", line 76, in report_detail
    user_feedback = AIReportFeedback.objects.filter(report=report, user=request.user).first()
  File "C:\Users\MSii\Desktop\Threat-Detection-and-Notification-Platform-by-Analyzing-Logs-of-Apache-and-MySQL-servers-\Venv\Lib\site-packages\django\db\models\query.py", line 1097, in first
    for obj in queryset[:1]:
               ~~~~~~~~^^^^
  File "C:\Users\MSii\Desktop\Threat-Detection-and-Notification-Platform-by-Analyzing-Logs-of-Apache-and-MySQL-servers-\Venv\Lib\site-packages\django\db\models\query.py", line 400, in __iter__
    self._fetch_all()
    ~~~~~~~~~~~~~~~^^
  File "C:\Users\MSii\Desktop\Threat-Detection-and-Notification-Platform-by-Analyzing-Logs-of-Apache-and-MySQL-servers-\Venv\Lib\site-packages\django\db\models\query.py", line 1928, in _fetch_all
    self._result_cache = list(self._iterable_class(self))
                         ~~~~^^^^^^^^^^^^^^^^^^^^^^^^^^^^
  File "C:\Users\MSii\Desktop\Threat-Detection-and-Notification-Platform-by-Analyzing-Logs-of-Apache-and-MySQL-servers-\Venv\Lib\site-packages\django\db\models\query.py", line 91, in __iter__
    results = compiler.execute_sql(
        chunked_fetch=self.chunked_fetch, chunk_size=self.chunk_size
    )
  File "C:\Users\MSii\Desktop\Threat-Detection-and-Notification-Platform-by-Analyzing-Logs-of-Apache-and-MySQL-servers-\Venv\Lib\site-packages\django\db\models\sql\compiler.py", line 1574, in execute_sql
    cursor.execute(sql, params)
    ~~~~~~~~~~~~~~^^^^^^^^^^^^^
  File "C:\Users\MSii\Desktop\Threat-Detection-and-Notification-Platform-by-Analyzing-Logs-of-Apache-and-MySQL-servers-\Venv\Lib\site-packages\django\db\backends\utils.py", line 122, in execute
    return super().execute(sql, params)
           ~~~~~~~~~~~~~~~^^^^^^^^^^^^^
  File "C:\Users\MSii\Desktop\Threat-Detection-and-Notification-Platform-by-Analyzing-Logs-of-Apache-and-MySQL-servers-\Venv\Lib\site-packages\django\db\backends\utils.py", line 79, in execute
    return self._execute_with_wrappers(
           ~~~~~~~~~~~~~~~~~~~~~~~~~~~^
        sql, params, many=False, executor=self._execute
        ^^^^^^^^^^^^^^^^^^^^^^^^^^^^^^^^^^^^^^^^^^^^^^^
    )
    ^
  File "C:\Users\MSii\Desktop\Threat-Detection-and-Notification-Platform-by-Analyzing-Logs-of-Apache-and-MySQL-servers-\Venv\Lib\site-packages\django\db\backends\utils.py", line 92, in _execute_with_wrappers
    return executor(sql, params, many, context)
  File "C:\Users\MSii\Desktop\Threat-Detection-and-Notification-Platform-by-Analyzing-Logs-of-Apache-and-MySQL-servers-\Venv\Lib\site-packages\django\db\backends\utils.py", line 100, in _execute
    with self.db.wrap_database_errors:
         ^^^^^^^^^^^^^^^^^^^^^^^^^^^^
  File "C:\Users\MSii\Desktop\Threat-Detection-and-Notification-Platform-by-Analyzing-Logs-of-Apache-and-MySQL-servers-\Venv\Lib\site-packages\django\db\utils.py", line 91, in __exit__
    raise dj_exc_value.with_traceback(traceback) from exc_value
  File "C:\Users\MSii\Desktop\Threat-Detection-and-Notification-Platform-by-Analyzing-Logs-of-Apache-and-MySQL-servers-\Venv\Lib\site-packages\django\db\backends\utils.py", line 105, in _execute
    return self.cursor.execute(sql, params)
           ~~~~~~~~~~~~~~~~~~~^^^^^^^^^^^^^
  File "C:\Users\MSii\Desktop\Threat-Detection-and-Notification-Platform-by-Analyzing-Logs-of-Apache-and-MySQL-servers-\Venv\Lib\site-packages\django\db\backends\mysql\base.py", line 76, in execute
    return self.cursor.execute(query, args)
           ~~~~~~~~~~~~~~~~~~~^^^^^^^^^^^^^
  File "C:\Users\MSii\Desktop\Threat-Detection-and-Notification-Platform-by-Analyzing-Logs-of-Apache-and-MySQL-servers-\Venv\Lib\site-packages\MySQLdb\cursors.py", line 179, in execute
    res = self._query(mogrified_query)
  File "C:\Users\MSii\Desktop\Threat-Detection-and-Notification-Platform-by-Analyzing-Logs-of-Apache-and-MySQL-servers-\Venv\Lib\site-packages\MySQLdb\cursors.py", line 330, in _query
    db.query(q)
    ~~~~~~~~^^^
  File "C:\Users\MSii\Desktop\Threat-Detection-and-Notification-Platform-by-Analyzing-Logs-of-Apache-and-MySQL-servers-\Venv\Lib\site-packages\MySQLdb\connections.py", line 280, in query
    _mysql.connection.query(self, query)
    ~~~~~~~~~~~~~~~~~~~~~~~^^^^^^^^^^^^^
django.db.utils.OperationalError: (1054, "Unknown column 'ai_analytics_aireportfeedback.created_at' in 'SELECT'")
Error in report_detail: (1054, "Unknown column 'ai_analytics_aireportfeedback.created_at' in 'SELECT'")
Traceback (most recent call last):
  File "C:\Users\MSii\Desktop\Threat-Detection-and-Notification-Platform-by-Analyzing-Logs-of-Apache-and-MySQL-servers-\Venv\Lib\site-packages\django\db\backends\utils.py", line 105, in _execute
    return self.cursor.execute(sql, params)
           ~~~~~~~~~~~~~~~~~~~^^^^^^^^^^^^^
  File "C:\Users\MSii\Desktop\Threat-Detection-and-Notification-Platform-by-Analyzing-Logs-of-Apache-and-MySQL-servers-\Venv\Lib\site-packages\django\db\backends\mysql\base.py", line 76, in execute
    return self.cursor.execute(query, args)
           ~~~~~~~~~~~~~~~~~~~^^^^^^^^^^^^^
  File "C:\Users\MSii\Desktop\Threat-Detection-and-Notification-Platform-by-Analyzing-Logs-of-Apache-and-MySQL-servers-\Venv\Lib\site-packages\MySQLdb\cursors.py", line 179, in execute
    res = self._query(mogrified_query)
  File "C:\Users\MSii\Desktop\Threat-Detection-and-Notification-Platform-by-Analyzing-Logs-of-Apache-and-MySQL-servers-\Venv\Lib\site-packages\MySQLdb\cursors.py", line 330, in _query
    db.query(q)
    ~~~~~~~~^^^
  File "C:\Users\MSii\Desktop\Threat-Detection-and-Notification-Platform-by-Analyzing-Logs-of-Apache-and-MySQL-servers-\Venv\Lib\site-packages\MySQLdb\connections.py", line 280, in query
    _mysql.connection.query(self, query)
    ~~~~~~~~~~~~~~~~~~~~~~~^^^^^^^^^^^^^
MySQLdb.OperationalError: (1054, "Unknown column 'ai_analytics_aireportfeedback.created_at' in 'SELECT'")

The above exception was the direct cause of the following exception:

Traceback (most recent call last):
  File "C:\Users\MSii\Desktop\Threat-Detection-and-Notification-Platform-by-Analyzing-Logs-of-Apache-and-MySQL-servers-\ai_analytics\views.py", line 76, in report_detail
    user_feedback = AIReportFeedback.objects.filter(report=report, user=request.user).first()
  File "C:\Users\MSii\Desktop\Threat-Detection-and-Notification-Platform-by-Analyzing-Logs-of-Apache-and-MySQL-servers-\Venv\Lib\site-packages\django\db\models\query.py", line 1097, in first
    for obj in queryset[:1]:
               ~~~~~~~~^^^^
  File "C:\Users\MSii\Desktop\Threat-Detection-and-Notification-Platform-by-Analyzing-Logs-of-Apache-and-MySQL-servers-\Venv\Lib\site-packages\django\db\models\query.py", line 400, in __iter__
    self._fetch_all()
    ~~~~~~~~~~~~~~~^^
  File "C:\Users\MSii\Desktop\Threat-Detection-and-Notification-Platform-by-Analyzing-Logs-of-Apache-and-MySQL-servers-\Venv\Lib\site-packages\django\db\models\query.py", line 1928, in _fetch_all
    self._result_cache = list(self._iterable_class(self))
                         ~~~~^^^^^^^^^^^^^^^^^^^^^^^^^^^^
  File "C:\Users\MSii\Desktop\Threat-Detection-and-Notification-Platform-by-Analyzing-Logs-of-Apache-and-MySQL-servers-\Venv\Lib\site-packages\django\db\models\query.py", line 91, in __iter__
    results = compiler.execute_sql(
        chunked_fetch=self.chunked_fetch, chunk_size=self.chunk_size
    )
  File "C:\Users\MSii\Desktop\Threat-Detection-and-Notification-Platform-by-Analyzing-Logs-of-Apache-and-MySQL-servers-\Venv\Lib\site-packages\django\db\models\sql\compiler.py", line 1574, in execute_sql
    cursor.execute(sql, params)
    ~~~~~~~~~~~~~~^^^^^^^^^^^^^
  File "C:\Users\MSii\Desktop\Threat-Detection-and-Notification-Platform-by-Analyzing-Logs-of-Apache-and-MySQL-servers-\Venv\Lib\site-packages\django\db\backends\utils.py", line 122, in execute
    return super().execute(sql, params)
           ~~~~~~~~~~~~~~~^^^^^^^^^^^^^
  File "C:\Users\MSii\Desktop\Threat-Detection-and-Notification-Platform-by-Analyzing-Logs-of-Apache-and-MySQL-servers-\Venv\Lib\site-packages\django\db\backends\utils.py", line 79, in execute
    return self._execute_with_wrappers(
           ~~~~~~~~~~~~~~~~~~~~~~~~~~~^
        sql, params, many=False, executor=self._execute
        ^^^^^^^^^^^^^^^^^^^^^^^^^^^^^^^^^^^^^^^^^^^^^^^
    )
    ^
  File "C:\Users\MSii\Desktop\Threat-Detection-and-Notification-Platform-by-Analyzing-Logs-of-Apache-and-MySQL-servers-\Venv\Lib\site-packages\django\db\backends\utils.py", line 92, in _execute_with_wrappers
    return executor(sql, params, many, context)
  File "C:\Users\MSii\Desktop\Threat-Detection-and-Notification-Platform-by-Analyzing-Logs-of-Apache-and-MySQL-servers-\Venv\Lib\site-packages\django\db\backends\utils.py", line 100, in _execute
    with self.db.wrap_database_errors:
         ^^^^^^^^^^^^^^^^^^^^^^^^^^^^
  File "C:\Users\MSii\Desktop\Threat-Detection-and-Notification-Platform-by-Analyzing-Logs-of-Apache-and-MySQL-servers-\Venv\Lib\site-packages\django\db\utils.py", line 91, in __exit__
    raise dj_exc_value.with_traceback(traceback) from exc_value
  File "C:\Users\MSii\Desktop\Threat-Detection-and-Notification-Platform-by-Analyzing-Logs-of-Apache-and-MySQL-servers-\Venv\Lib\site-packages\django\db\backends\utils.py", line 105, in _execute
    return self.cursor.execute(sql, params)
           ~~~~~~~~~~~~~~~~~~~^^^^^^^^^^^^^
  File "C:\Users\MSii\Desktop\Threat-Detection-and-Notification-Platform-by-Analyzing-Logs-of-Apache-and-MySQL-servers-\Venv\Lib\site-packages\django\db\backends\mysql\base.py", line 76, in execute
    return self.cursor.execute(query, args)
           ~~~~~~~~~~~~~~~~~~~^^^^^^^^^^^^^
  File "C:\Users\MSii\Desktop\Threat-Detection-and-Notification-Platform-by-Analyzing-Logs-of-Apache-and-MySQL-servers-\Venv\Lib\site-packages\MySQLdb\cursors.py", line 179, in execute
    res = self._query(mogrified_query)
  File "C:\Users\MSii\Desktop\Threat-Detection-and-Notification-Platform-by-Analyzing-Logs-of-Apache-and-MySQL-servers-\Venv\Lib\site-packages\MySQLdb\cursors.py", line 330, in _query
    db.query(q)
    ~~~~~~~~^^^
  File "C:\Users\MSii\Desktop\Threat-Detection-and-Notification-Platform-by-Analyzing-Logs-of-Apache-and-MySQL-servers-\Venv\Lib\site-packages\MySQLdb\connections.py", line 280, in query
    _mysql.connection.query(self, query)
    ~~~~~~~~~~~~~~~~~~~~~~~^^^^^^^^^^^^^
django.db.utils.OperationalError: (1054, "Unknown column 'ai_analytics_aireportfeedback.created_at' in 'SELECT'")
Error in report_detail: (1054, "Unknown column 'ai_analytics_aireportfeedback.created_at' in 'SELECT'")
Traceback (most recent call last):
  File "C:\Users\MSii\Desktop\Threat-Detection-and-Notification-Platform-by-Analyzing-Logs-of-Apache-and-MySQL-servers-\Venv\Lib\site-packages\django\db\backends\utils.py", line 105, in _execute
    return self.cursor.execute(sql, params)
           ~~~~~~~~~~~~~~~~~~~^^^^^^^^^^^^^
  File "C:\Users\MSii\Desktop\Threat-Detection-and-Notification-Platform-by-Analyzing-Logs-of-Apache-and-MySQL-servers-\Venv\Lib\site-packages\django\db\backends\mysql\base.py", line 76, in execute
    return self.cursor.execute(query, args)
           ~~~~~~~~~~~~~~~~~~~^^^^^^^^^^^^^
  File "C:\Users\MSii\Desktop\Threat-Detection-and-Notification-Platform-by-Analyzing-Logs-of-Apache-and-MySQL-servers-\Venv\Lib\site-packages\MySQLdb\cursors.py", line 179, in execute
    res = self._query(mogrified_query)
  File "C:\Users\MSii\Desktop\Threat-Detection-and-Notification-Platform-by-Analyzing-Logs-of-Apache-and-MySQL-servers-\Venv\Lib\site-packages\MySQLdb\cursors.py", line 330, in _query
    db.query(q)
    ~~~~~~~~^^^
  File "C:\Users\MSii\Desktop\Threat-Detection-and-Notification-Platform-by-Analyzing-Logs-of-Apache-and-MySQL-servers-\Venv\Lib\site-packages\MySQLdb\connections.py", line 280, in query
    _mysql.connection.query(self, query)
    ~~~~~~~~~~~~~~~~~~~~~~~^^^^^^^^^^^^^
MySQLdb.OperationalError: (1054, "Unknown column 'ai_analytics_aireportfeedback.created_at' in 'SELECT'")

The above exception was the direct cause of the following exception:

Traceback (most recent call last):
  File "C:\Users\MSii\Desktop\Threat-Detection-and-Notification-Platform-by-Analyzing-Logs-of-Apache-and-MySQL-servers-\ai_analytics\views.py", line 76, in report_detail
    user_feedback = AIReportFeedback.objects.filter(report=report, user=request.user).first()
  File "C:\Users\MSii\Desktop\Threat-Detection-and-Notification-Platform-by-Analyzing-Logs-of-Apache-and-MySQL-servers-\Venv\Lib\site-packages\django\db\models\query.py", line 1097, in first
    for obj in queryset[:1]:
               ~~~~~~~~^^^^
  File "C:\Users\MSii\Desktop\Threat-Detection-and-Notification-Platform-by-Analyzing-Logs-of-Apache-and-MySQL-servers-\Venv\Lib\site-packages\django\db\models\query.py", line 400, in __iter__
    self._fetch_all()
    ~~~~~~~~~~~~~~~^^
  File "C:\Users\MSii\Desktop\Threat-Detection-and-Notification-Platform-by-Analyzing-Logs-of-Apache-and-MySQL-servers-\Venv\Lib\site-packages\django\db\models\query.py", line 1928, in _fetch_all
    self._result_cache = list(self._iterable_class(self))
                         ~~~~^^^^^^^^^^^^^^^^^^^^^^^^^^^^
  File "C:\Users\MSii\Desktop\Threat-Detection-and-Notification-Platform-by-Analyzing-Logs-of-Apache-and-MySQL-servers-\Venv\Lib\site-packages\django\db\models\query.py", line 91, in __iter__
    results = compiler.execute_sql(
        chunked_fetch=self.chunked_fetch, chunk_size=self.chunk_size
    )
  File "C:\Users\MSii\Desktop\Threat-Detection-and-Notification-Platform-by-Analyzing-Logs-of-Apache-and-MySQL-servers-\Venv\Lib\site-packages\django\db\models\sql\compiler.py", line 1574, in execute_sql
    cursor.execute(sql, params)
    ~~~~~~~~~~~~~~^^^^^^^^^^^^^
  File "C:\Users\MSii\Desktop\Threat-Detection-and-Notification-Platform-by-Analyzing-Logs-of-Apache-and-MySQL-servers-\Venv\Lib\site-packages\django\db\backends\utils.py", line 122, in execute
    return super().execute(sql, params)
           ~~~~~~~~~~~~~~~^^^^^^^^^^^^^
  File "C:\Users\MSii\Desktop\Threat-Detection-and-Notification-Platform-by-Analyzing-Logs-of-Apache-and-MySQL-servers-\Venv\Lib\site-packages\django\db\backends\utils.py", line 79, in execute
    return self._execute_with_wrappers(
           ~~~~~~~~~~~~~~~~~~~~~~~~~~~^
        sql, params, many=False, executor=self._execute
        ^^^^^^^^^^^^^^^^^^^^^^^^^^^^^^^^^^^^^^^^^^^^^^^
    )
    ^
  File "C:\Users\MSii\Desktop\Threat-Detection-and-Notification-Platform-by-Analyzing-Logs-of-Apache-and-MySQL-servers-\Venv\Lib\site-packages\django\db\backends\utils.py", line 92, in _execute_with_wrappers
    return executor(sql, params, many, context)
  File "C:\Users\MSii\Desktop\Threat-Detection-and-Notification-Platform-by-Analyzing-Logs-of-Apache-and-MySQL-servers-\Venv\Lib\site-packages\django\db\backends\utils.py", line 100, in _execute
    with self.db.wrap_database_errors:
         ^^^^^^^^^^^^^^^^^^^^^^^^^^^^
  File "C:\Users\MSii\Desktop\Threat-Detection-and-Notification-Platform-by-Analyzing-Logs-of-Apache-and-MySQL-servers-\Venv\Lib\site-packages\django\db\utils.py", line 91, in __exit__
    raise dj_exc_value.with_traceback(traceback) from exc_value
  File "C:\Users\MSii\Desktop\Threat-Detection-and-Notification-Platform-by-Analyzing-Logs-of-Apache-and-MySQL-servers-\Venv\Lib\site-packages\django\db\backends\utils.py", line 105, in _execute
    return self.cursor.execute(sql, params)
           ~~~~~~~~~~~~~~~~~~~^^^^^^^^^^^^^
  File "C:\Users\MSii\Desktop\Threat-Detection-and-Notification-Platform-by-Analyzing-Logs-of-Apache-and-MySQL-servers-\Venv\Lib\site-packages\django\db\backends\mysql\base.py", line 76, in execute
    return self.cursor.execute(query, args)
           ~~~~~~~~~~~~~~~~~~~^^^^^^^^^^^^^
  File "C:\Users\MSii\Desktop\Threat-Detection-and-Notification-Platform-by-Analyzing-Logs-of-Apache-and-MySQL-servers-\Venv\Lib\site-packages\MySQLdb\cursors.py", line 179, in execute
    res = self._query(mogrified_query)
  File "C:\Users\MSii\Desktop\Threat-Detection-and-Notification-Platform-by-Analyzing-Logs-of-Apache-and-MySQL-servers-\Venv\Lib\site-packages\MySQLdb\cursors.py", line 330, in _query
    db.query(q)
    ~~~~~~~~^^^
  File "C:\Users\MSii\Desktop\Threat-Detection-and-Notification-Platform-by-Analyzing-Logs-of-Apache-and-MySQL-servers-\Venv\Lib\site-packages\MySQLdb\connections.py", line 280, in query
    _mysql.connection.query(self, query)
    ~~~~~~~~~~~~~~~~~~~~~~~^^^^^^^^^^^^^
django.db.utils.OperationalError: (1054, "Unknown column 'ai_analytics_aireportfeedback.created_at' in 'SELECT'")
Error in report_detail: (1054, "Unknown column 'ai_analytics_aireportfeedback.created_at' in 'SELECT'")
Traceback (most recent call last):
  File "C:\Users\MSii\Desktop\Threat-Detection-and-Notification-Platform-by-Analyzing-Logs-of-Apache-and-MySQL-servers-\Venv\Lib\site-packages\django\db\backends\utils.py", line 105, in _execute
    return self.cursor.execute(sql, params)
           ~~~~~~~~~~~~~~~~~~~^^^^^^^^^^^^^
  File "C:\Users\MSii\Desktop\Threat-Detection-and-Notification-Platform-by-Analyzing-Logs-of-Apache-and-MySQL-servers-\Venv\Lib\site-packages\django\db\backends\mysql\base.py", line 76, in execute
    return self.cursor.execute(query, args)
           ~~~~~~~~~~~~~~~~~~~^^^^^^^^^^^^^
  File "C:\Users\MSii\Desktop\Threat-Detection-and-Notification-Platform-by-Analyzing-Logs-of-Apache-and-MySQL-servers-\Venv\Lib\site-packages\MySQLdb\cursors.py", line 179, in execute
    res = self._query(mogrified_query)
  File "C:\Users\MSii\Desktop\Threat-Detection-and-Notification-Platform-by-Analyzing-Logs-of-Apache-and-MySQL-servers-\Venv\Lib\site-packages\MySQLdb\cursors.py", line 330, in _query
    db.query(q)
    ~~~~~~~~^^^
  File "C:\Users\MSii\Desktop\Threat-Detection-and-Notification-Platform-by-Analyzing-Logs-of-Apache-and-MySQL-servers-\Venv\Lib\site-packages\MySQLdb\connections.py", line 280, in query
    _mysql.connection.query(self, query)
    ~~~~~~~~~~~~~~~~~~~~~~~^^^^^^^^^^^^^
MySQLdb.OperationalError: (1054, "Unknown column 'ai_analytics_aireportfeedback.created_at' in 'SELECT'")

The above exception was the direct cause of the following exception:

Traceback (most recent call last):
  File "C:\Users\MSii\Desktop\Threat-Detection-and-Notification-Platform-by-Analyzing-Logs-of-Apache-and-MySQL-servers-\ai_analytics\views.py", line 76, in report_detail
    user_feedback = AIReportFeedback.objects.filter(report=report, user=request.user).first()
  File "C:\Users\MSii\Desktop\Threat-Detection-and-Notification-Platform-by-Analyzing-Logs-of-Apache-and-MySQL-servers-\Venv\Lib\site-packages\django\db\models\query.py", line 1097, in first
    for obj in queryset[:1]:
               ~~~~~~~~^^^^
  File "C:\Users\MSii\Desktop\Threat-Detection-and-Notification-Platform-by-Analyzing-Logs-of-Apache-and-MySQL-servers-\Venv\Lib\site-packages\django\db\models\query.py", line 400, in __iter__
    self._fetch_all()
    ~~~~~~~~~~~~~~~^^
  File "C:\Users\MSii\Desktop\Threat-Detection-and-Notification-Platform-by-Analyzing-Logs-of-Apache-and-MySQL-servers-\Venv\Lib\site-packages\django\db\models\query.py", line 1928, in _fetch_all
    self._result_cache = list(self._iterable_class(self))
                         ~~~~^^^^^^^^^^^^^^^^^^^^^^^^^^^^
  File "C:\Users\MSii\Desktop\Threat-Detection-and-Notification-Platform-by-Analyzing-Logs-of-Apache-and-MySQL-servers-\Venv\Lib\site-packages\django\db\models\query.py", line 91, in __iter__
    results = compiler.execute_sql(
        chunked_fetch=self.chunked_fetch, chunk_size=self.chunk_size
    )
  File "C:\Users\MSii\Desktop\Threat-Detection-and-Notification-Platform-by-Analyzing-Logs-of-Apache-and-MySQL-servers-\Venv\Lib\site-packages\django\db\models\sql\compiler.py", line 1574, in execute_sql
    cursor.execute(sql, params)
    ~~~~~~~~~~~~~~^^^^^^^^^^^^^
  File "C:\Users\MSii\Desktop\Threat-Detection-and-Notification-Platform-by-Analyzing-Logs-of-Apache-and-MySQL-servers-\Venv\Lib\site-packages\django\db\backends\utils.py", line 122, in execute
    return super().execute(sql, params)
           ~~~~~~~~~~~~~~~^^^^^^^^^^^^^
  File "C:\Users\MSii\Desktop\Threat-Detection-and-Notification-Platform-by-Analyzing-Logs-of-Apache-and-MySQL-servers-\Venv\Lib\site-packages\django\db\backends\utils.py", line 79, in execute
    return self._execute_with_wrappers(
           ~~~~~~~~~~~~~~~~~~~~~~~~~~~^
        sql, params, many=False, executor=self._execute
        ^^^^^^^^^^^^^^^^^^^^^^^^^^^^^^^^^^^^^^^^^^^^^^^
    )
    ^
  File "C:\Users\MSii\Desktop\Threat-Detection-and-Notification-Platform-by-Analyzing-Logs-of-Apache-and-MySQL-servers-\Venv\Lib\site-packages\django\db\backends\utils.py", line 92, in _execute_with_wrappers
    return executor(sql, params, many, context)
  File "C:\Users\MSii\Desktop\Threat-Detection-and-Notification-Platform-by-Analyzing-Logs-of-Apache-and-MySQL-servers-\Venv\Lib\site-packages\django\db\backends\utils.py", line 100, in _execute
    with self.db.wrap_database_errors:
         ^^^^^^^^^^^^^^^^^^^^^^^^^^^^
  File "C:\Users\MSii\Desktop\Threat-Detection-and-Notification-Platform-by-Analyzing-Logs-of-Apache-and-MySQL-servers-\Venv\Lib\site-packages\django\db\utils.py", line 91, in __exit__
    raise dj_exc_value.with_traceback(traceback) from exc_value
  File "C:\Users\MSii\Desktop\Threat-Detection-and-Notification-Platform-by-Analyzing-Logs-of-Apache-and-MySQL-servers-\Venv\Lib\site-packages\django\db\backends\utils.py", line 105, in _execute
    return self.cursor.execute(sql, params)
           ~~~~~~~~~~~~~~~~~~~^^^^^^^^^^^^^
  File "C:\Users\MSii\Desktop\Threat-Detection-and-Notification-Platform-by-Analyzing-Logs-of-Apache-and-MySQL-servers-\Venv\Lib\site-packages\django\db\backends\mysql\base.py", line 76, in execute
    return self.cursor.execute(query, args)
           ~~~~~~~~~~~~~~~~~~~^^^^^^^^^^^^^
  File "C:\Users\MSii\Desktop\Threat-Detection-and-Notification-Platform-by-Analyzing-Logs-of-Apache-and-MySQL-servers-\Venv\Lib\site-packages\MySQLdb\cursors.py", line 179, in execute
    res = self._query(mogrified_query)
  File "C:\Users\MSii\Desktop\Threat-Detection-and-Notification-Platform-by-Analyzing-Logs-of-Apache-and-MySQL-servers-\Venv\Lib\site-packages\MySQLdb\cursors.py", line 330, in _query
    db.query(q)
    ~~~~~~~~^^^
  File "C:\Users\MSii\Desktop\Threat-Detection-and-Notification-Platform-by-Analyzing-Logs-of-Apache-and-MySQL-servers-\Venv\Lib\site-packages\MySQLdb\connections.py", line 280, in query
    _mysql.connection.query(self, query)
    ~~~~~~~~~~~~~~~~~~~~~~~^^^^^^^^^^^^^
django.db.utils.OperationalError: (1054, "Unknown column 'ai_analytics_aireportfeedback.created_at' in 'SELECT'")
Error in report_detail: (1054, "Unknown column 'ai_analytics_aireportfeedback.created_at' in 'SELECT'")
Traceback (most recent call last):
  File "C:\Users\MSii\Desktop\Threat-Detection-and-Notification-Platform-by-Analyzing-Logs-of-Apache-and-MySQL-servers-\Venv\Lib\site-packages\django\db\backends\utils.py", line 105, in _execute
    return self.cursor.execute(sql, params)
           ~~~~~~~~~~~~~~~~~~~^^^^^^^^^^^^^
  File "C:\Users\MSii\Desktop\Threat-Detection-and-Notification-Platform-by-Analyzing-Logs-of-Apache-and-MySQL-servers-\Venv\Lib\site-packages\django\db\backends\mysql\base.py", line 76, in execute
    return self.cursor.execute(query, args)
           ~~~~~~~~~~~~~~~~~~~^^^^^^^^^^^^^
  File "C:\Users\MSii\Desktop\Threat-Detection-and-Notification-Platform-by-Analyzing-Logs-of-Apache-and-MySQL-servers-\Venv\Lib\site-packages\MySQLdb\cursors.py", line 179, in execute
    res = self._query(mogrified_query)
  File "C:\Users\MSii\Desktop\Threat-Detection-and-Notification-Platform-by-Analyzing-Logs-of-Apache-and-MySQL-servers-\Venv\Lib\site-packages\MySQLdb\cursors.py", line 330, in _query
    db.query(q)
    ~~~~~~~~^^^
  File "C:\Users\MSii\Desktop\Threat-Detection-and-Notification-Platform-by-Analyzing-Logs-of-Apache-and-MySQL-servers-\Venv\Lib\site-packages\MySQLdb\connections.py", line 280, in query
    _mysql.connection.query(self, query)
    ~~~~~~~~~~~~~~~~~~~~~~~^^^^^^^^^^^^^
MySQLdb.OperationalError: (1054, "Unknown column 'ai_analytics_aireportfeedback.created_at' in 'SELECT'")

The above exception was the direct cause of the following exception:

Traceback (most recent call last):
  File "C:\Users\MSii\Desktop\Threat-Detection-and-Notification-Platform-by-Analyzing-Logs-of-Apache-and-MySQL-servers-\ai_analytics\views.py", line 76, in report_detail
    user_feedback = AIReportFeedback.objects.filter(report=report, user=request.user).first()
  File "C:\Users\MSii\Desktop\Threat-Detection-and-Notification-Platform-by-Analyzing-Logs-of-Apache-and-MySQL-servers-\Venv\Lib\site-packages\django\db\models\query.py", line 1097, in first
    for obj in queryset[:1]:
               ~~~~~~~~^^^^
  File "C:\Users\MSii\Desktop\Threat-Detection-and-Notification-Platform-by-Analyzing-Logs-of-Apache-and-MySQL-servers-\Venv\Lib\site-packages\django\db\models\query.py", line 400, in __iter__
    self._fetch_all()
    ~~~~~~~~~~~~~~~^^
  File "C:\Users\MSii\Desktop\Threat-Detection-and-Notification-Platform-by-Analyzing-Logs-of-Apache-and-MySQL-servers-\Venv\Lib\site-packages\django\db\models\query.py", line 1928, in _fetch_all
    self._result_cache = list(self._iterable_class(self))
                         ~~~~^^^^^^^^^^^^^^^^^^^^^^^^^^^^
  File "C:\Users\MSii\Desktop\Threat-Detection-and-Notification-Platform-by-Analyzing-Logs-of-Apache-and-MySQL-servers-\Venv\Lib\site-packages\django\db\models\query.py", line 91, in __iter__
    results = compiler.execute_sql(
        chunked_fetch=self.chunked_fetch, chunk_size=self.chunk_size
    )
  File "C:\Users\MSii\Desktop\Threat-Detection-and-Notification-Platform-by-Analyzing-Logs-of-Apache-and-MySQL-servers-\Venv\Lib\site-packages\django\db\models\sql\compiler.py", line 1574, in execute_sql
    cursor.execute(sql, params)
    ~~~~~~~~~~~~~~^^^^^^^^^^^^^
  File "C:\Users\MSii\Desktop\Threat-Detection-and-Notification-Platform-by-Analyzing-Logs-of-Apache-and-MySQL-servers-\Venv\Lib\site-packages\django\db\backends\utils.py", line 122, in execute
    return super().execute(sql, params)
           ~~~~~~~~~~~~~~~^^^^^^^^^^^^^
  File "C:\Users\MSii\Desktop\Threat-Detection-and-Notification-Platform-by-Analyzing-Logs-of-Apache-and-MySQL-servers-\Venv\Lib\site-packages\django\db\backends\utils.py", line 79, in execute
    return self._execute_with_wrappers(
           ~~~~~~~~~~~~~~~~~~~~~~~~~~~^
        sql, params, many=False, executor=self._execute
        ^^^^^^^^^^^^^^^^^^^^^^^^^^^^^^^^^^^^^^^^^^^^^^^
    )
    ^
  File "C:\Users\MSii\Desktop\Threat-Detection-and-Notification-Platform-by-Analyzing-Logs-of-Apache-and-MySQL-servers-\Venv\Lib\site-packages\django\db\backends\utils.py", line 92, in _execute_with_wrappers
    return executor(sql, params, many, context)
  File "C:\Users\MSii\Desktop\Threat-Detection-and-Notification-Platform-by-Analyzing-Logs-of-Apache-and-MySQL-servers-\Venv\Lib\site-packages\django\db\backends\utils.py", line 100, in _execute
    with self.db.wrap_database_errors:
         ^^^^^^^^^^^^^^^^^^^^^^^^^^^^
  File "C:\Users\MSii\Desktop\Threat-Detection-and-Notification-Platform-by-Analyzing-Logs-of-Apache-and-MySQL-servers-\Venv\Lib\site-packages\django\db\utils.py", line 91, in __exit__
    raise dj_exc_value.with_traceback(traceback) from exc_value
  File "C:\Users\MSii\Desktop\Threat-Detection-and-Notification-Platform-by-Analyzing-Logs-of-Apache-and-MySQL-servers-\Venv\Lib\site-packages\django\db\backends\utils.py", line 105, in _execute
    return self.cursor.execute(sql, params)
           ~~~~~~~~~~~~~~~~~~~^^^^^^^^^^^^^
  File "C:\Users\MSii\Desktop\Threat-Detection-and-Notification-Platform-by-Analyzing-Logs-of-Apache-and-MySQL-servers-\Venv\Lib\site-packages\django\db\backends\mysql\base.py", line 76, in execute
    return self.cursor.execute(query, args)
           ~~~~~~~~~~~~~~~~~~~^^^^^^^^^^^^^
  File "C:\Users\MSii\Desktop\Threat-Detection-and-Notification-Platform-by-Analyzing-Logs-of-Apache-and-MySQL-servers-\Venv\Lib\site-packages\MySQLdb\cursors.py", line 179, in execute
    res = self._query(mogrified_query)
  File "C:\Users\MSii\Desktop\Threat-Detection-and-Notification-Platform-by-Analyzing-Logs-of-Apache-and-MySQL-servers-\Venv\Lib\site-packages\MySQLdb\cursors.py", line 330, in _query
    db.query(q)
    ~~~~~~~~^^^
  File "C:\Users\MSii\Desktop\Threat-Detection-and-Notification-Platform-by-Analyzing-Logs-of-Apache-and-MySQL-servers-\Venv\Lib\site-packages\MySQLdb\connections.py", line 280, in query
    _mysql.connection.query(self, query)
    ~~~~~~~~~~~~~~~~~~~~~~~^^^^^^^^^^^^^
django.db.utils.OperationalError: (1054, "Unknown column 'ai_analytics_aireportfeedback.created_at' in 'SELECT'")
Error in report_detail: (1054, "Unknown column 'ai_analytics_aireportfeedback.created_at' in 'SELECT'")
Traceback (most recent call last):
  File "C:\Users\MSii\Desktop\Threat-Detection-and-Notification-Platform-by-Analyzing-Logs-of-Apache-and-MySQL-servers-\Venv\Lib\site-packages\django\db\backends\utils.py", line 105, in _execute
    return self.cursor.execute(sql, params)
           ~~~~~~~~~~~~~~~~~~~^^^^^^^^^^^^^
  File "C:\Users\MSii\Desktop\Threat-Detection-and-Notification-Platform-by-Analyzing-Logs-of-Apache-and-MySQL-servers-\Venv\Lib\site-packages\django\db\backends\mysql\base.py", line 76, in execute
    return self.cursor.execute(query, args)
           ~~~~~~~~~~~~~~~~~~~^^^^^^^^^^^^^
  File "C:\Users\MSii\Desktop\Threat-Detection-and-Notification-Platform-by-Analyzing-Logs-of-Apache-and-MySQL-servers-\Venv\Lib\site-packages\MySQLdb\cursors.py", line 179, in execute
    res = self._query(mogrified_query)
  File "C:\Users\MSii\Desktop\Threat-Detection-and-Notification-Platform-by-Analyzing-Logs-of-Apache-and-MySQL-servers-\Venv\Lib\site-packages\MySQLdb\cursors.py", line 330, in _query
    db.query(q)
    ~~~~~~~~^^^
  File "C:\Users\MSii\Desktop\Threat-Detection-and-Notification-Platform-by-Analyzing-Logs-of-Apache-and-MySQL-servers-\Venv\Lib\site-packages\MySQLdb\connections.py", line 280, in query
    _mysql.connection.query(self, query)
    ~~~~~~~~~~~~~~~~~~~~~~~^^^^^^^^^^^^^
MySQLdb.OperationalError: (1054, "Unknown column 'ai_analytics_aireportfeedback.created_at' in 'SELECT'")

The above exception was the direct cause of the following exception:

Traceback (most recent call last):
  File "C:\Users\MSii\Desktop\Threat-Detection-and-Notification-Platform-by-Analyzing-Logs-of-Apache-and-MySQL-servers-\ai_analytics\views.py", line 76, in report_detail
    user_feedback = AIReportFeedback.objects.filter(report=report, user=request.user).first()
  File "C:\Users\MSii\Desktop\Threat-Detection-and-Notification-Platform-by-Analyzing-Logs-of-Apache-and-MySQL-servers-\Venv\Lib\site-packages\django\db\models\query.py", line 1097, in first
    for obj in queryset[:1]:
               ~~~~~~~~^^^^
  File "C:\Users\MSii\Desktop\Threat-Detection-and-Notification-Platform-by-Analyzing-Logs-of-Apache-and-MySQL-servers-\Venv\Lib\site-packages\django\db\models\query.py", line 400, in __iter__
    self._fetch_all()
    ~~~~~~~~~~~~~~~^^
  File "C:\Users\MSii\Desktop\Threat-Detection-and-Notification-Platform-by-Analyzing-Logs-of-Apache-and-MySQL-servers-\Venv\Lib\site-packages\django\db\models\query.py", line 1928, in _fetch_all
    self._result_cache = list(self._iterable_class(self))
                         ~~~~^^^^^^^^^^^^^^^^^^^^^^^^^^^^
  File "C:\Users\MSii\Desktop\Threat-Detection-and-Notification-Platform-by-Analyzing-Logs-of-Apache-and-MySQL-servers-\Venv\Lib\site-packages\django\db\models\query.py", line 91, in __iter__
    results = compiler.execute_sql(
        chunked_fetch=self.chunked_fetch, chunk_size=self.chunk_size
    )
  File "C:\Users\MSii\Desktop\Threat-Detection-and-Notification-Platform-by-Analyzing-Logs-of-Apache-and-MySQL-servers-\Venv\Lib\site-packages\django\db\models\sql\compiler.py", line 1574, in execute_sql
    cursor.execute(sql, params)
    ~~~~~~~~~~~~~~^^^^^^^^^^^^^
  File "C:\Users\MSii\Desktop\Threat-Detection-and-Notification-Platform-by-Analyzing-Logs-of-Apache-and-MySQL-servers-\Venv\Lib\site-packages\django\db\backends\utils.py", line 122, in execute
    return super().execute(sql, params)
           ~~~~~~~~~~~~~~~^^^^^^^^^^^^^
  File "C:\Users\MSii\Desktop\Threat-Detection-and-Notification-Platform-by-Analyzing-Logs-of-Apache-and-MySQL-servers-\Venv\Lib\site-packages\django\db\backends\utils.py", line 79, in execute
    return self._execute_with_wrappers(
           ~~~~~~~~~~~~~~~~~~~~~~~~~~~^
        sql, params, many=False, executor=self._execute
        ^^^^^^^^^^^^^^^^^^^^^^^^^^^^^^^^^^^^^^^^^^^^^^^
    )
    ^
  File "C:\Users\MSii\Desktop\Threat-Detection-and-Notification-Platform-by-Analyzing-Logs-of-Apache-and-MySQL-servers-\Venv\Lib\site-packages\django\db\backends\utils.py", line 92, in _execute_with_wrappers
    return executor(sql, params, many, context)
  File "C:\Users\MSii\Desktop\Threat-Detection-and-Notification-Platform-by-Analyzing-Logs-of-Apache-and-MySQL-servers-\Venv\Lib\site-packages\django\db\backends\utils.py", line 100, in _execute
    with self.db.wrap_database_errors:
         ^^^^^^^^^^^^^^^^^^^^^^^^^^^^
  File "C:\Users\MSii\Desktop\Threat-Detection-and-Notification-Platform-by-Analyzing-Logs-of-Apache-and-MySQL-servers-\Venv\Lib\site-packages\django\db\utils.py", line 91, in __exit__
    raise dj_exc_value.with_traceback(traceback) from exc_value
  File "C:\Users\MSii\Desktop\Threat-Detection-and-Notification-Platform-by-Analyzing-Logs-of-Apache-and-MySQL-servers-\Venv\Lib\site-packages\django\db\backends\utils.py", line 105, in _execute
    return self.cursor.execute(sql, params)
           ~~~~~~~~~~~~~~~~~~~^^^^^^^^^^^^^
  File "C:\Users\MSii\Desktop\Threat-Detection-and-Notification-Platform-by-Analyzing-Logs-of-Apache-and-MySQL-servers-\Venv\Lib\site-packages\django\db\backends\mysql\base.py", line 76, in execute
    return self.cursor.execute(query, args)
           ~~~~~~~~~~~~~~~~~~~^^^^^^^^^^^^^
  File "C:\Users\MSii\Desktop\Threat-Detection-and-Notification-Platform-by-Analyzing-Logs-of-Apache-and-MySQL-servers-\Venv\Lib\site-packages\MySQLdb\cursors.py", line 179, in execute
    res = self._query(mogrified_query)
  File "C:\Users\MSii\Desktop\Threat-Detection-and-Notification-Platform-by-Analyzing-Logs-of-Apache-and-MySQL-servers-\Venv\Lib\site-packages\MySQLdb\cursors.py", line 330, in _query
    db.query(q)
    ~~~~~~~~^^^
  File "C:\Users\MSii\Desktop\Threat-Detection-and-Notification-Platform-by-Analyzing-Logs-of-Apache-and-MySQL-servers-\Venv\Lib\site-packages\MySQLdb\connections.py", line 280, in query
    _mysql.connection.query(self, query)
    ~~~~~~~~~~~~~~~~~~~~~~~^^^^^^^^^^^^^
django.db.utils.OperationalError: (1054, "Unknown column 'ai_analytics_aireportfeedback.created_at' in 'SELECT'")
Error in report_detail: (1054, "Unknown column 'ai_analytics_aireportfeedback.created_at' in 'SELECT'")
Traceback (most recent call last):
  File "C:\Users\MSii\Desktop\Threat-Detection-and-Notification-Platform-by-Analyzing-Logs-of-Apache-and-MySQL-servers-\Venv\Lib\site-packages\django\db\backends\utils.py", line 105, in _execute
    return self.cursor.execute(sql, params)
           ~~~~~~~~~~~~~~~~~~~^^^^^^^^^^^^^
  File "C:\Users\MSii\Desktop\Threat-Detection-and-Notification-Platform-by-Analyzing-Logs-of-Apache-and-MySQL-servers-\Venv\Lib\site-packages\django\db\backends\mysql\base.py", line 76, in execute
    return self.cursor.execute(query, args)
           ~~~~~~~~~~~~~~~~~~~^^^^^^^^^^^^^
  File "C:\Users\MSii\Desktop\Threat-Detection-and-Notification-Platform-by-Analyzing-Logs-of-Apache-and-MySQL-servers-\Venv\Lib\site-packages\MySQLdb\cursors.py", line 179, in execute
    res = self._query(mogrified_query)
  File "C:\Users\MSii\Desktop\Threat-Detection-and-Notification-Platform-by-Analyzing-Logs-of-Apache-and-MySQL-servers-\Venv\Lib\site-packages\MySQLdb\cursors.py", line 330, in _query
    db.query(q)
    ~~~~~~~~^^^
  File "C:\Users\MSii\Desktop\Threat-Detection-and-Notification-Platform-by-Analyzing-Logs-of-Apache-and-MySQL-servers-\Venv\Lib\site-packages\MySQLdb\connections.py", line 280, in query
    _mysql.connection.query(self, query)
    ~~~~~~~~~~~~~~~~~~~~~~~^^^^^^^^^^^^^
MySQLdb.OperationalError: (1054, "Unknown column 'ai_analytics_aireportfeedback.created_at' in 'SELECT'")

The above exception was the direct cause of the following exception:

Traceback (most recent call last):
  File "C:\Users\MSii\Desktop\Threat-Detection-and-Notification-Platform-by-Analyzing-Logs-of-Apache-and-MySQL-servers-\ai_analytics\views.py", line 76, in report_detail
    user_feedback = AIReportFeedback.objects.filter(report=report, user=request.user).first()
  File "C:\Users\MSii\Desktop\Threat-Detection-and-Notification-Platform-by-Analyzing-Logs-of-Apache-and-MySQL-servers-\Venv\Lib\site-packages\django\db\models\query.py", line 1097, in first
    for obj in queryset[:1]:
               ~~~~~~~~^^^^
  File "C:\Users\MSii\Desktop\Threat-Detection-and-Notification-Platform-by-Analyzing-Logs-of-Apache-and-MySQL-servers-\Venv\Lib\site-packages\django\db\models\query.py", line 400, in __iter__
    self._fetch_all()
    ~~~~~~~~~~~~~~~^^
  File "C:\Users\MSii\Desktop\Threat-Detection-and-Notification-Platform-by-Analyzing-Logs-of-Apache-and-MySQL-servers-\Venv\Lib\site-packages\django\db\models\query.py", line 1928, in _fetch_all
    self._result_cache = list(self._iterable_class(self))
                         ~~~~^^^^^^^^^^^^^^^^^^^^^^^^^^^^
  File "C:\Users\MSii\Desktop\Threat-Detection-and-Notification-Platform-by-Analyzing-Logs-of-Apache-and-MySQL-servers-\Venv\Lib\site-packages\django\db\models\query.py", line 91, in __iter__
    results = compiler.execute_sql(
        chunked_fetch=self.chunked_fetch, chunk_size=self.chunk_size
    )
  File "C:\Users\MSii\Desktop\Threat-Detection-and-Notification-Platform-by-Analyzing-Logs-of-Apache-and-MySQL-servers-\Venv\Lib\site-packages\django\db\models\sql\compiler.py", line 1574, in execute_sql
    cursor.execute(sql, params)
    ~~~~~~~~~~~~~~^^^^^^^^^^^^^
  File "C:\Users\MSii\Desktop\Threat-Detection-and-Notification-Platform-by-Analyzing-Logs-of-Apache-and-MySQL-servers-\Venv\Lib\site-packages\django\db\backends\utils.py", line 122, in execute
    return super().execute(sql, params)
           ~~~~~~~~~~~~~~~^^^^^^^^^^^^^
  File "C:\Users\MSii\Desktop\Threat-Detection-and-Notification-Platform-by-Analyzing-Logs-of-Apache-and-MySQL-servers-\Venv\Lib\site-packages\django\db\backends\utils.py", line 79, in execute
    return self._execute_with_wrappers(
           ~~~~~~~~~~~~~~~~~~~~~~~~~~~^
        sql, params, many=False, executor=self._execute
        ^^^^^^^^^^^^^^^^^^^^^^^^^^^^^^^^^^^^^^^^^^^^^^^
    )
    ^
  File "C:\Users\MSii\Desktop\Threat-Detection-and-Notification-Platform-by-Analyzing-Logs-of-Apache-and-MySQL-servers-\Venv\Lib\site-packages\django\db\backends\utils.py", line 92, in _execute_with_wrappers
    return executor(sql, params, many, context)
  File "C:\Users\MSii\Desktop\Threat-Detection-and-Notification-Platform-by-Analyzing-Logs-of-Apache-and-MySQL-servers-\Venv\Lib\site-packages\django\db\backends\utils.py", line 100, in _execute
    with self.db.wrap_database_errors:
         ^^^^^^^^^^^^^^^^^^^^^^^^^^^^
  File "C:\Users\MSii\Desktop\Threat-Detection-and-Notification-Platform-by-Analyzing-Logs-of-Apache-and-MySQL-servers-\Venv\Lib\site-packages\django\db\utils.py", line 91, in __exit__
    raise dj_exc_value.with_traceback(traceback) from exc_value
  File "C:\Users\MSii\Desktop\Threat-Detection-and-Notification-Platform-by-Analyzing-Logs-of-Apache-and-MySQL-servers-\Venv\Lib\site-packages\django\db\backends\utils.py", line 105, in _execute
    return self.cursor.execute(sql, params)
           ~~~~~~~~~~~~~~~~~~~^^^^^^^^^^^^^
  File "C:\Users\MSii\Desktop\Threat-Detection-and-Notification-Platform-by-Analyzing-Logs-of-Apache-and-MySQL-servers-\Venv\Lib\site-packages\django\db\backends\mysql\base.py", line 76, in execute
    return self.cursor.execute(query, args)
           ~~~~~~~~~~~~~~~~~~~^^^^^^^^^^^^^
  File "C:\Users\MSii\Desktop\Threat-Detection-and-Notification-Platform-by-Analyzing-Logs-of-Apache-and-MySQL-servers-\Venv\Lib\site-packages\MySQLdb\cursors.py", line 179, in execute
    res = self._query(mogrified_query)
  File "C:\Users\MSii\Desktop\Threat-Detection-and-Notification-Platform-by-Analyzing-Logs-of-Apache-and-MySQL-servers-\Venv\Lib\site-packages\MySQLdb\cursors.py", line 330, in _query
    db.query(q)
    ~~~~~~~~^^^
  File "C:\Users\MSii\Desktop\Threat-Detection-and-Notification-Platform-by-Analyzing-Logs-of-Apache-and-MySQL-servers-\Venv\Lib\site-packages\MySQLdb\connections.py", line 280, in query
    _mysql.connection.query(self, query)
    ~~~~~~~~~~~~~~~~~~~~~~~^^^^^^^^^^^^^
django.db.utils.OperationalError: (1054, "Unknown column 'ai_analytics_aireportfeedback.created_at' in 'SELECT'")
Error in report_detail: (1054, "Unknown column 'ai_analytics_aireportfeedback.created_at' in 'SELECT'")
Traceback (most recent call last):
  File "C:\Users\MSii\Desktop\Threat-Detection-and-Notification-Platform-by-Analyzing-Logs-of-Apache-and-MySQL-servers-\Venv\Lib\site-packages\django\db\backends\utils.py", line 105, in _execute
    return self.cursor.execute(sql, params)
           ~~~~~~~~~~~~~~~~~~~^^^^^^^^^^^^^
  File "C:\Users\MSii\Desktop\Threat-Detection-and-Notification-Platform-by-Analyzing-Logs-of-Apache-and-MySQL-servers-\Venv\Lib\site-packages\django\db\backends\mysql\base.py", line 76, in execute
    return self.cursor.execute(query, args)
           ~~~~~~~~~~~~~~~~~~~^^^^^^^^^^^^^
  File "C:\Users\MSii\Desktop\Threat-Detection-and-Notification-Platform-by-Analyzing-Logs-of-Apache-and-MySQL-servers-\Venv\Lib\site-packages\MySQLdb\cursors.py", line 179, in execute
    res = self._query(mogrified_query)
  File "C:\Users\MSii\Desktop\Threat-Detection-and-Notification-Platform-by-Analyzing-Logs-of-Apache-and-MySQL-servers-\Venv\Lib\site-packages\MySQLdb\cursors.py", line 330, in _query
    db.query(q)
    ~~~~~~~~^^^
  File "C:\Users\MSii\Desktop\Threat-Detection-and-Notification-Platform-by-Analyzing-Logs-of-Apache-and-MySQL-servers-\Venv\Lib\site-packages\MySQLdb\connections.py", line 280, in query
    _mysql.connection.query(self, query)
    ~~~~~~~~~~~~~~~~~~~~~~~^^^^^^^^^^^^^
MySQLdb.OperationalError: (1054, "Unknown column 'ai_analytics_aireportfeedback.created_at' in 'SELECT'")

The above exception was the direct cause of the following exception:

Traceback (most recent call last):
  File "C:\Users\MSii\Desktop\Threat-Detection-and-Notification-Platform-by-Analyzing-Logs-of-Apache-and-MySQL-servers-\ai_analytics\views.py", line 76, in report_detail
    user_feedback = AIReportFeedback.objects.filter(report=report, user=request.user).first()
  File "C:\Users\MSii\Desktop\Threat-Detection-and-Notification-Platform-by-Analyzing-Logs-of-Apache-and-MySQL-servers-\Venv\Lib\site-packages\django\db\models\query.py", line 1097, in first
    for obj in queryset[:1]:
               ~~~~~~~~^^^^
  File "C:\Users\MSii\Desktop\Threat-Detection-and-Notification-Platform-by-Analyzing-Logs-of-Apache-and-MySQL-servers-\Venv\Lib\site-packages\django\db\models\query.py", line 400, in __iter__
    self._fetch_all()
    ~~~~~~~~~~~~~~~^^
  File "C:\Users\MSii\Desktop\Threat-Detection-and-Notification-Platform-by-Analyzing-Logs-of-Apache-and-MySQL-servers-\Venv\Lib\site-packages\django\db\models\query.py", line 1928, in _fetch_all
    self._result_cache = list(self._iterable_class(self))
                         ~~~~^^^^^^^^^^^^^^^^^^^^^^^^^^^^
  File "C:\Users\MSii\Desktop\Threat-Detection-and-Notification-Platform-by-Analyzing-Logs-of-Apache-and-MySQL-servers-\Venv\Lib\site-packages\django\db\models\query.py", line 91, in __iter__
    results = compiler.execute_sql(
        chunked_fetch=self.chunked_fetch, chunk_size=self.chunk_size
    )
  File "C:\Users\MSii\Desktop\Threat-Detection-and-Notification-Platform-by-Analyzing-Logs-of-Apache-and-MySQL-servers-\Venv\Lib\site-packages\django\db\models\sql\compiler.py", line 1574, in execute_sql
    cursor.execute(sql, params)
    ~~~~~~~~~~~~~~^^^^^^^^^^^^^
  File "C:\Users\MSii\Desktop\Threat-Detection-and-Notification-Platform-by-Analyzing-Logs-of-Apache-and-MySQL-servers-\Venv\Lib\site-packages\django\db\backends\utils.py", line 122, in execute
    return super().execute(sql, params)
           ~~~~~~~~~~~~~~~^^^^^^^^^^^^^
  File "C:\Users\MSii\Desktop\Threat-Detection-and-Notification-Platform-by-Analyzing-Logs-of-Apache-and-MySQL-servers-\Venv\Lib\site-packages\django\db\backends\utils.py", line 79, in execute
    return self._execute_with_wrappers(
           ~~~~~~~~~~~~~~~~~~~~~~~~~~~^
        sql, params, many=False, executor=self._execute
        ^^^^^^^^^^^^^^^^^^^^^^^^^^^^^^^^^^^^^^^^^^^^^^^
    )
    ^
  File "C:\Users\MSii\Desktop\Threat-Detection-and-Notification-Platform-by-Analyzing-Logs-of-Apache-and-MySQL-servers-\Venv\Lib\site-packages\django\db\backends\utils.py", line 92, in _execute_with_wrappers
    return executor(sql, params, many, context)
  File "C:\Users\MSii\Desktop\Threat-Detection-and-Notification-Platform-by-Analyzing-Logs-of-Apache-and-MySQL-servers-\Venv\Lib\site-packages\django\db\backends\utils.py", line 100, in _execute
    with self.db.wrap_database_errors:
         ^^^^^^^^^^^^^^^^^^^^^^^^^^^^
  File "C:\Users\MSii\Desktop\Threat-Detection-and-Notification-Platform-by-Analyzing-Logs-of-Apache-and-MySQL-servers-\Venv\Lib\site-packages\django\db\utils.py", line 91, in __exit__
    raise dj_exc_value.with_traceback(traceback) from exc_value
  File "C:\Users\MSii\Desktop\Threat-Detection-and-Notification-Platform-by-Analyzing-Logs-of-Apache-and-MySQL-servers-\Venv\Lib\site-packages\django\db\backends\utils.py", line 105, in _execute
    return self.cursor.execute(sql, params)
           ~~~~~~~~~~~~~~~~~~~^^^^^^^^^^^^^
  File "C:\Users\MSii\Desktop\Threat-Detection-and-Notification-Platform-by-Analyzing-Logs-of-Apache-and-MySQL-servers-\Venv\Lib\site-packages\django\db\backends\mysql\base.py", line 76, in execute
    return self.cursor.execute(query, args)
           ~~~~~~~~~~~~~~~~~~~^^^^^^^^^^^^^
  File "C:\Users\MSii\Desktop\Threat-Detection-and-Notification-Platform-by-Analyzing-Logs-of-Apache-and-MySQL-servers-\Venv\Lib\site-packages\MySQLdb\cursors.py", line 179, in execute
    res = self._query(mogrified_query)
  File "C:\Users\MSii\Desktop\Threat-Detection-and-Notification-Platform-by-Analyzing-Logs-of-Apache-and-MySQL-servers-\Venv\Lib\site-packages\MySQLdb\cursors.py", line 330, in _query
    db.query(q)
    ~~~~~~~~^^^
  File "C:\Users\MSii\Desktop\Threat-Detection-and-Notification-Platform-by-Analyzing-Logs-of-Apache-and-MySQL-servers-\Venv\Lib\site-packages\MySQLdb\connections.py", line 280, in query
    _mysql.connection.query(self, query)
    ~~~~~~~~~~~~~~~~~~~~~~~^^^^^^^^^^^^^
django.db.utils.OperationalError: (1054, "Unknown column 'ai_analytics_aireportfeedback.created_at' in 'SELECT'")
Error in report_detail: (1054, "Unknown column 'ai_analytics_aireportfeedback.created_at' in 'SELECT'")
Traceback (most recent call last):
  File "C:\Users\MSii\Desktop\Threat-Detection-and-Notification-Platform-by-Analyzing-Logs-of-Apache-and-MySQL-servers-\Venv\Lib\site-packages\django\db\backends\utils.py", line 105, in _execute
    return self.cursor.execute(sql, params)
           ~~~~~~~~~~~~~~~~~~~^^^^^^^^^^^^^
  File "C:\Users\MSii\Desktop\Threat-Detection-and-Notification-Platform-by-Analyzing-Logs-of-Apache-and-MySQL-servers-\Venv\Lib\site-packages\django\db\backends\mysql\base.py", line 76, in execute
    return self.cursor.execute(query, args)
           ~~~~~~~~~~~~~~~~~~~^^^^^^^^^^^^^
  File "C:\Users\MSii\Desktop\Threat-Detection-and-Notification-Platform-by-Analyzing-Logs-of-Apache-and-MySQL-servers-\Venv\Lib\site-packages\MySQLdb\cursors.py", line 179, in execute
    res = self._query(mogrified_query)
  File "C:\Users\MSii\Desktop\Threat-Detection-and-Notification-Platform-by-Analyzing-Logs-of-Apache-and-MySQL-servers-\Venv\Lib\site-packages\MySQLdb\cursors.py", line 330, in _query
    db.query(q)
    ~~~~~~~~^^^
  File "C:\Users\MSii\Desktop\Threat-Detection-and-Notification-Platform-by-Analyzing-Logs-of-Apache-and-MySQL-servers-\Venv\Lib\site-packages\MySQLdb\connections.py", line 280, in query
    _mysql.connection.query(self, query)
    ~~~~~~~~~~~~~~~~~~~~~~~^^^^^^^^^^^^^
MySQLdb.OperationalError: (1054, "Unknown column 'ai_analytics_aireportfeedback.created_at' in 'SELECT'")

The above exception was the direct cause of the following exception:

Traceback (most recent call last):
  File "C:\Users\MSii\Desktop\Threat-Detection-and-Notification-Platform-by-Analyzing-Logs-of-Apache-and-MySQL-servers-\ai_analytics\views.py", line 76, in report_detail
    user_feedback = AIReportFeedback.objects.filter(report=report, user=request.user).first()
  File "C:\Users\MSii\Desktop\Threat-Detection-and-Notification-Platform-by-Analyzing-Logs-of-Apache-and-MySQL-servers-\Venv\Lib\site-packages\django\db\models\query.py", line 1097, in first
    for obj in queryset[:1]:
               ~~~~~~~~^^^^
  File "C:\Users\MSii\Desktop\Threat-Detection-and-Notification-Platform-by-Analyzing-Logs-of-Apache-and-MySQL-servers-\Venv\Lib\site-packages\django\db\models\query.py", line 400, in __iter__
    self._fetch_all()
    ~~~~~~~~~~~~~~~^^
  File "C:\Users\MSii\Desktop\Threat-Detection-and-Notification-Platform-by-Analyzing-Logs-of-Apache-and-MySQL-servers-\Venv\Lib\site-packages\django\db\models\query.py", line 1928, in _fetch_all
    self._result_cache = list(self._iterable_class(self))
                         ~~~~^^^^^^^^^^^^^^^^^^^^^^^^^^^^
  File "C:\Users\MSii\Desktop\Threat-Detection-and-Notification-Platform-by-Analyzing-Logs-of-Apache-and-MySQL-servers-\Venv\Lib\site-packages\django\db\models\query.py", line 91, in __iter__
    results = compiler.execute_sql(
        chunked_fetch=self.chunked_fetch, chunk_size=self.chunk_size
    )
  File "C:\Users\MSii\Desktop\Threat-Detection-and-Notification-Platform-by-Analyzing-Logs-of-Apache-and-MySQL-servers-\Venv\Lib\site-packages\django\db\models\sql\compiler.py", line 1574, in execute_sql
    cursor.execute(sql, params)
    ~~~~~~~~~~~~~~^^^^^^^^^^^^^
  File "C:\Users\MSii\Desktop\Threat-Detection-and-Notification-Platform-by-Analyzing-Logs-of-Apache-and-MySQL-servers-\Venv\Lib\site-packages\django\db\backends\utils.py", line 122, in execute
    return super().execute(sql, params)
           ~~~~~~~~~~~~~~~^^^^^^^^^^^^^
  File "C:\Users\MSii\Desktop\Threat-Detection-and-Notification-Platform-by-Analyzing-Logs-of-Apache-and-MySQL-servers-\Venv\Lib\site-packages\django\db\backends\utils.py", line 79, in execute
    return self._execute_with_wrappers(
           ~~~~~~~~~~~~~~~~~~~~~~~~~~~^
        sql, params, many=False, executor=self._execute
        ^^^^^^^^^^^^^^^^^^^^^^^^^^^^^^^^^^^^^^^^^^^^^^^
    )
    ^
  File "C:\Users\MSii\Desktop\Threat-Detection-and-Notification-Platform-by-Analyzing-Logs-of-Apache-and-MySQL-servers-\Venv\Lib\site-packages\django\db\backends\utils.py", line 92, in _execute_with_wrappers
    return executor(sql, params, many, context)
  File "C:\Users\MSii\Desktop\Threat-Detection-and-Notification-Platform-by-Analyzing-Logs-of-Apache-and-MySQL-servers-\Venv\Lib\site-packages\django\db\backends\utils.py", line 100, in _execute
    with self.db.wrap_database_errors:
         ^^^^^^^^^^^^^^^^^^^^^^^^^^^^
  File "C:\Users\MSii\Desktop\Threat-Detection-and-Notification-Platform-by-Analyzing-Logs-of-Apache-and-MySQL-servers-\Venv\Lib\site-packages\django\db\utils.py", line 91, in __exit__
    raise dj_exc_value.with_traceback(traceback) from exc_value
  File "C:\Users\MSii\Desktop\Threat-Detection-and-Notification-Platform-by-Analyzing-Logs-of-Apache-and-MySQL-servers-\Venv\Lib\site-packages\django\db\backends\utils.py", line 105, in _execute
    return self.cursor.execute(sql, params)
           ~~~~~~~~~~~~~~~~~~~^^^^^^^^^^^^^
  File "C:\Users\MSii\Desktop\Threat-Detection-and-Notification-Platform-by-Analyzing-Logs-of-Apache-and-MySQL-servers-\Venv\Lib\site-packages\django\db\backends\mysql\base.py", line 76, in execute
    return self.cursor.execute(query, args)
           ~~~~~~~~~~~~~~~~~~~^^^^^^^^^^^^^
  File "C:\Users\MSii\Desktop\Threat-Detection-and-Notification-Platform-by-Analyzing-Logs-of-Apache-and-MySQL-servers-\Venv\Lib\site-packages\MySQLdb\cursors.py", line 179, in execute
    res = self._query(mogrified_query)
  File "C:\Users\MSii\Desktop\Threat-Detection-and-Notification-Platform-by-Analyzing-Logs-of-Apache-and-MySQL-servers-\Venv\Lib\site-packages\MySQLdb\cursors.py", line 330, in _query
    db.query(q)
    ~~~~~~~~^^^
  File "C:\Users\MSii\Desktop\Threat-Detection-and-Notification-Platform-by-Analyzing-Logs-of-Apache-and-MySQL-servers-\Venv\Lib\site-packages\MySQLdb\connections.py", line 280, in query
    _mysql.connection.query(self, query)
    ~~~~~~~~~~~~~~~~~~~~~~~^^^^^^^^^^^^^
django.db.utils.OperationalError: (1054, "Unknown column 'ai_analytics_aireportfeedback.created_at' in 'SELECT'")
Error in report_detail: (1054, "Unknown column 'ai_analytics_aireportfeedback.created_at' in 'SELECT'")
Traceback (most recent call last):
  File "C:\Users\MSii\Desktop\Threat-Detection-and-Notification-Platform-by-Analyzing-Logs-of-Apache-and-MySQL-servers-\Venv\Lib\site-packages\django\db\backends\utils.py", line 105, in _execute
    return self.cursor.execute(sql, params)
           ~~~~~~~~~~~~~~~~~~~^^^^^^^^^^^^^
  File "C:\Users\MSii\Desktop\Threat-Detection-and-Notification-Platform-by-Analyzing-Logs-of-Apache-and-MySQL-servers-\Venv\Lib\site-packages\django\db\backends\mysql\base.py", line 76, in execute
    return self.cursor.execute(query, args)
           ~~~~~~~~~~~~~~~~~~~^^^^^^^^^^^^^
  File "C:\Users\MSii\Desktop\Threat-Detection-and-Notification-Platform-by-Analyzing-Logs-of-Apache-and-MySQL-servers-\Venv\Lib\site-packages\MySQLdb\cursors.py", line 179, in execute
    res = self._query(mogrified_query)
  File "C:\Users\MSii\Desktop\Threat-Detection-and-Notification-Platform-by-Analyzing-Logs-of-Apache-and-MySQL-servers-\Venv\Lib\site-packages\MySQLdb\cursors.py", line 330, in _query
    db.query(q)
    ~~~~~~~~^^^
  File "C:\Users\MSii\Desktop\Threat-Detection-and-Notification-Platform-by-Analyzing-Logs-of-Apache-and-MySQL-servers-\Venv\Lib\site-packages\MySQLdb\connections.py", line 280, in query
    _mysql.connection.query(self, query)
    ~~~~~~~~~~~~~~~~~~~~~~~^^^^^^^^^^^^^
MySQLdb.OperationalError: (1054, "Unknown column 'ai_analytics_aireportfeedback.created_at' in 'SELECT'")

The above exception was the direct cause of the following exception:

Traceback (most recent call last):
  File "C:\Users\MSii\Desktop\Threat-Detection-and-Notification-Platform-by-Analyzing-Logs-of-Apache-and-MySQL-servers-\ai_analytics\views.py", line 76, in report_detail
    user_feedback = AIReportFeedback.objects.filter(report=report, user=request.user).first()
  File "C:\Users\MSii\Desktop\Threat-Detection-and-Notification-Platform-by-Analyzing-Logs-of-Apache-and-MySQL-servers-\Venv\Lib\site-packages\django\db\models\query.py", line 1097, in first
    for obj in queryset[:1]:
               ~~~~~~~~^^^^
  File "C:\Users\MSii\Desktop\Threat-Detection-and-Notification-Platform-by-Analyzing-Logs-of-Apache-and-MySQL-servers-\Venv\Lib\site-packages\django\db\models\query.py", line 400, in __iter__
    self._fetch_all()
    ~~~~~~~~~~~~~~~^^
  File "C:\Users\MSii\Desktop\Threat-Detection-and-Notification-Platform-by-Analyzing-Logs-of-Apache-and-MySQL-servers-\Venv\Lib\site-packages\django\db\models\query.py", line 1928, in _fetch_all
    self._result_cache = list(self._iterable_class(self))
                         ~~~~^^^^^^^^^^^^^^^^^^^^^^^^^^^^
  File "C:\Users\MSii\Desktop\Threat-Detection-and-Notification-Platform-by-Analyzing-Logs-of-Apache-and-MySQL-servers-\Venv\Lib\site-packages\django\db\models\query.py", line 91, in __iter__
    results = compiler.execute_sql(
        chunked_fetch=self.chunked_fetch, chunk_size=self.chunk_size
    )
  File "C:\Users\MSii\Desktop\Threat-Detection-and-Notification-Platform-by-Analyzing-Logs-of-Apache-and-MySQL-servers-\Venv\Lib\site-packages\django\db\models\sql\compiler.py", line 1574, in execute_sql
    cursor.execute(sql, params)
    ~~~~~~~~~~~~~~^^^^^^^^^^^^^
  File "C:\Users\MSii\Desktop\Threat-Detection-and-Notification-Platform-by-Analyzing-Logs-of-Apache-and-MySQL-servers-\Venv\Lib\site-packages\django\db\backends\utils.py", line 122, in execute
    return super().execute(sql, params)
           ~~~~~~~~~~~~~~~^^^^^^^^^^^^^
  File "C:\Users\MSii\Desktop\Threat-Detection-and-Notification-Platform-by-Analyzing-Logs-of-Apache-and-MySQL-servers-\Venv\Lib\site-packages\django\db\backends\utils.py", line 79, in execute
    return self._execute_with_wrappers(
           ~~~~~~~~~~~~~~~~~~~~~~~~~~~^
        sql, params, many=False, executor=self._execute
        ^^^^^^^^^^^^^^^^^^^^^^^^^^^^^^^^^^^^^^^^^^^^^^^
    )
    ^
  File "C:\Users\MSii\Desktop\Threat-Detection-and-Notification-Platform-by-Analyzing-Logs-of-Apache-and-MySQL-servers-\Venv\Lib\site-packages\django\db\backends\utils.py", line 92, in _execute_with_wrappers
    return executor(sql, params, many, context)
  File "C:\Users\MSii\Desktop\Threat-Detection-and-Notification-Platform-by-Analyzing-Logs-of-Apache-and-MySQL-servers-\Venv\Lib\site-packages\django\db\backends\utils.py", line 100, in _execute
    with self.db.wrap_database_errors:
         ^^^^^^^^^^^^^^^^^^^^^^^^^^^^
  File "C:\Users\MSii\Desktop\Threat-Detection-and-Notification-Platform-by-Analyzing-Logs-of-Apache-and-MySQL-servers-\Venv\Lib\site-packages\django\db\utils.py", line 91, in __exit__
    raise dj_exc_value.with_traceback(traceback) from exc_value
  File "C:\Users\MSii\Desktop\Threat-Detection-and-Notification-Platform-by-Analyzing-Logs-of-Apache-and-MySQL-servers-\Venv\Lib\site-packages\django\db\backends\utils.py", line 105, in _execute
    return self.cursor.execute(sql, params)
           ~~~~~~~~~~~~~~~~~~~^^^^^^^^^^^^^
  File "C:\Users\MSii\Desktop\Threat-Detection-and-Notification-Platform-by-Analyzing-Logs-of-Apache-and-MySQL-servers-\Venv\Lib\site-packages\django\db\backends\mysql\base.py", line 76, in execute
    return self.cursor.execute(query, args)
           ~~~~~~~~~~~~~~~~~~~^^^^^^^^^^^^^
  File "C:\Users\MSii\Desktop\Threat-Detection-and-Notification-Platform-by-Analyzing-Logs-of-Apache-and-MySQL-servers-\Venv\Lib\site-packages\MySQLdb\cursors.py", line 179, in execute
    res = self._query(mogrified_query)
  File "C:\Users\MSii\Desktop\Threat-Detection-and-Notification-Platform-by-Analyzing-Logs-of-Apache-and-MySQL-servers-\Venv\Lib\site-packages\MySQLdb\cursors.py", line 330, in _query
    db.query(q)
    ~~~~~~~~^^^
  File "C:\Users\MSii\Desktop\Threat-Detection-and-Notification-Platform-by-Analyzing-Logs-of-Apache-and-MySQL-servers-\Venv\Lib\site-packages\MySQLdb\connections.py", line 280, in query
    _mysql.connection.query(self, query)
    ~~~~~~~~~~~~~~~~~~~~~~~^^^^^^^^^^^^^
django.db.utils.OperationalError: (1054, "Unknown column 'ai_analytics_aireportfeedback.created_at' in 'SELECT'")
Error in report_detail: (1054, "Unknown column 'ai_analytics_aireportfeedback.created_at' in 'SELECT'")
Traceback (most recent call last):
  File "C:\Users\MSii\Desktop\Threat-Detection-and-Notification-Platform-by-Analyzing-Logs-of-Apache-and-MySQL-servers-\Venv\Lib\site-packages\django\db\backends\utils.py", line 105, in _execute
    return self.cursor.execute(sql, params)
           ~~~~~~~~~~~~~~~~~~~^^^^^^^^^^^^^
  File "C:\Users\MSii\Desktop\Threat-Detection-and-Notification-Platform-by-Analyzing-Logs-of-Apache-and-MySQL-servers-\Venv\Lib\site-packages\django\db\backends\mysql\base.py", line 76, in execute
    return self.cursor.execute(query, args)
           ~~~~~~~~~~~~~~~~~~~^^^^^^^^^^^^^
  File "C:\Users\MSii\Desktop\Threat-Detection-and-Notification-Platform-by-Analyzing-Logs-of-Apache-and-MySQL-servers-\Venv\Lib\site-packages\MySQLdb\cursors.py", line 179, in execute
    res = self._query(mogrified_query)
  File "C:\Users\MSii\Desktop\Threat-Detection-and-Notification-Platform-by-Analyzing-Logs-of-Apache-and-MySQL-servers-\Venv\Lib\site-packages\MySQLdb\cursors.py", line 330, in _query
    db.query(q)
    ~~~~~~~~^^^
  File "C:\Users\MSii\Desktop\Threat-Detection-and-Notification-Platform-by-Analyzing-Logs-of-Apache-and-MySQL-servers-\Venv\Lib\site-packages\MySQLdb\connections.py", line 280, in query
    _mysql.connection.query(self, query)
    ~~~~~~~~~~~~~~~~~~~~~~~^^^^^^^^^^^^^
MySQLdb.OperationalError: (1054, "Unknown column 'ai_analytics_aireportfeedback.created_at' in 'SELECT'")

The above exception was the direct cause of the following exception:

Traceback (most recent call last):
  File "C:\Users\MSii\Desktop\Threat-Detection-and-Notification-Platform-by-Analyzing-Logs-of-Apache-and-MySQL-servers-\ai_analytics\views.py", line 76, in report_detail
    user_feedback = AIReportFeedback.objects.filter(report=report, user=request.user).first()
  File "C:\Users\MSii\Desktop\Threat-Detection-and-Notification-Platform-by-Analyzing-Logs-of-Apache-and-MySQL-servers-\Venv\Lib\site-packages\django\db\models\query.py", line 1097, in first
    for obj in queryset[:1]:
               ~~~~~~~~^^^^
  File "C:\Users\MSii\Desktop\Threat-Detection-and-Notification-Platform-by-Analyzing-Logs-of-Apache-and-MySQL-servers-\Venv\Lib\site-packages\django\db\models\query.py", line 400, in __iter__
    self._fetch_all()
    ~~~~~~~~~~~~~~~^^
  File "C:\Users\MSii\Desktop\Threat-Detection-and-Notification-Platform-by-Analyzing-Logs-of-Apache-and-MySQL-servers-\Venv\Lib\site-packages\django\db\models\query.py", line 1928, in _fetch_all
    self._result_cache = list(self._iterable_class(self))
                         ~~~~^^^^^^^^^^^^^^^^^^^^^^^^^^^^
  File "C:\Users\MSii\Desktop\Threat-Detection-and-Notification-Platform-by-Analyzing-Logs-of-Apache-and-MySQL-servers-\Venv\Lib\site-packages\django\db\models\query.py", line 91, in __iter__
    results = compiler.execute_sql(
        chunked_fetch=self.chunked_fetch, chunk_size=self.chunk_size
    )
  File "C:\Users\MSii\Desktop\Threat-Detection-and-Notification-Platform-by-Analyzing-Logs-of-Apache-and-MySQL-servers-\Venv\Lib\site-packages\django\db\models\sql\compiler.py", line 1574, in execute_sql
    cursor.execute(sql, params)
    ~~~~~~~~~~~~~~^^^^^^^^^^^^^
  File "C:\Users\MSii\Desktop\Threat-Detection-and-Notification-Platform-by-Analyzing-Logs-of-Apache-and-MySQL-servers-\Venv\Lib\site-packages\django\db\backends\utils.py", line 122, in execute
    return super().execute(sql, params)
           ~~~~~~~~~~~~~~~^^^^^^^^^^^^^
  File "C:\Users\MSii\Desktop\Threat-Detection-and-Notification-Platform-by-Analyzing-Logs-of-Apache-and-MySQL-servers-\Venv\Lib\site-packages\django\db\backends\utils.py", line 79, in execute
    return self._execute_with_wrappers(
           ~~~~~~~~~~~~~~~~~~~~~~~~~~~^
        sql, params, many=False, executor=self._execute
        ^^^^^^^^^^^^^^^^^^^^^^^^^^^^^^^^^^^^^^^^^^^^^^^
    )
    ^
  File "C:\Users\MSii\Desktop\Threat-Detection-and-Notification-Platform-by-Analyzing-Logs-of-Apache-and-MySQL-servers-\Venv\Lib\site-packages\django\db\backends\utils.py", line 92, in _execute_with_wrappers
    return executor(sql, params, many, context)
  File "C:\Users\MSii\Desktop\Threat-Detection-and-Notification-Platform-by-Analyzing-Logs-of-Apache-and-MySQL-servers-\Venv\Lib\site-packages\django\db\backends\utils.py", line 100, in _execute
    with self.db.wrap_database_errors:
         ^^^^^^^^^^^^^^^^^^^^^^^^^^^^
  File "C:\Users\MSii\Desktop\Threat-Detection-and-Notification-Platform-by-Analyzing-Logs-of-Apache-and-MySQL-servers-\Venv\Lib\site-packages\django\db\utils.py", line 91, in __exit__
    raise dj_exc_value.with_traceback(traceback) from exc_value
  File "C:\Users\MSii\Desktop\Threat-Detection-and-Notification-Platform-by-Analyzing-Logs-of-Apache-and-MySQL-servers-\Venv\Lib\site-packages\django\db\backends\utils.py", line 105, in _execute
    return self.cursor.execute(sql, params)
           ~~~~~~~~~~~~~~~~~~~^^^^^^^^^^^^^
  File "C:\Users\MSii\Desktop\Threat-Detection-and-Notification-Platform-by-Analyzing-Logs-of-Apache-and-MySQL-servers-\Venv\Lib\site-packages\django\db\backends\mysql\base.py", line 76, in execute
    return self.cursor.execute(query, args)
           ~~~~~~~~~~~~~~~~~~~^^^^^^^^^^^^^
  File "C:\Users\MSii\Desktop\Threat-Detection-and-Notification-Platform-by-Analyzing-Logs-of-Apache-and-MySQL-servers-\Venv\Lib\site-packages\MySQLdb\cursors.py", line 179, in execute
    res = self._query(mogrified_query)
  File "C:\Users\MSii\Desktop\Threat-Detection-and-Notification-Platform-by-Analyzing-Logs-of-Apache-and-MySQL-servers-\Venv\Lib\site-packages\MySQLdb\cursors.py", line 330, in _query
    db.query(q)
    ~~~~~~~~^^^
  File "C:\Users\MSii\Desktop\Threat-Detection-and-Notification-Platform-by-Analyzing-Logs-of-Apache-and-MySQL-servers-\Venv\Lib\site-packages\MySQLdb\connections.py", line 280, in query
    _mysql.connection.query(self, query)
    ~~~~~~~~~~~~~~~~~~~~~~~^^^^^^^^^^^^^
django.db.utils.OperationalError: (1054, "Unknown column 'ai_analytics_aireportfeedback.created_at' in 'SELECT'")
Error in report_detail: (1054, "Unknown column 'ai_analytics_aireportfeedback.created_at' in 'SELECT'")
Traceback (most recent call last):
  File "C:\Users\MSii\Desktop\Threat-Detection-and-Notification-Platform-by-Analyzing-Logs-of-Apache-and-MySQL-servers-\Venv\Lib\site-packages\django\db\backends\utils.py", line 105, in _execute
    return self.cursor.execute(sql, params)
           ~~~~~~~~~~~~~~~~~~~^^^^^^^^^^^^^
  File "C:\Users\MSii\Desktop\Threat-Detection-and-Notification-Platform-by-Analyzing-Logs-of-Apache-and-MySQL-servers-\Venv\Lib\site-packages\django\db\backends\mysql\base.py", line 76, in execute
    return self.cursor.execute(query, args)
           ~~~~~~~~~~~~~~~~~~~^^^^^^^^^^^^^
  File "C:\Users\MSii\Desktop\Threat-Detection-and-Notification-Platform-by-Analyzing-Logs-of-Apache-and-MySQL-servers-\Venv\Lib\site-packages\MySQLdb\cursors.py", line 179, in execute
    res = self._query(mogrified_query)
  File "C:\Users\MSii\Desktop\Threat-Detection-and-Notification-Platform-by-Analyzing-Logs-of-Apache-and-MySQL-servers-\Venv\Lib\site-packages\MySQLdb\cursors.py", line 330, in _query
    db.query(q)
    ~~~~~~~~^^^
  File "C:\Users\MSii\Desktop\Threat-Detection-and-Notification-Platform-by-Analyzing-Logs-of-Apache-and-MySQL-servers-\Venv\Lib\site-packages\MySQLdb\connections.py", line 280, in query
    _mysql.connection.query(self, query)
    ~~~~~~~~~~~~~~~~~~~~~~~^^^^^^^^^^^^^
MySQLdb.OperationalError: (1054, "Unknown column 'ai_analytics_aireportfeedback.created_at' in 'SELECT'")

The above exception was the direct cause of the following exception:

Traceback (most recent call last):
  File "C:\Users\MSii\Desktop\Threat-Detection-and-Notification-Platform-by-Analyzing-Logs-of-Apache-and-MySQL-servers-\ai_analytics\views.py", line 76, in report_detail
    user_feedback = AIReportFeedback.objects.filter(report=report, user=request.user).first()
  File "C:\Users\MSii\Desktop\Threat-Detection-and-Notification-Platform-by-Analyzing-Logs-of-Apache-and-MySQL-servers-\Venv\Lib\site-packages\django\db\models\query.py", line 1097, in first
    for obj in queryset[:1]:
               ~~~~~~~~^^^^
  File "C:\Users\MSii\Desktop\Threat-Detection-and-Notification-Platform-by-Analyzing-Logs-of-Apache-and-MySQL-servers-\Venv\Lib\site-packages\django\db\models\query.py", line 400, in __iter__
    self._fetch_all()
    ~~~~~~~~~~~~~~~^^
  File "C:\Users\MSii\Desktop\Threat-Detection-and-Notification-Platform-by-Analyzing-Logs-of-Apache-and-MySQL-servers-\Venv\Lib\site-packages\django\db\models\query.py", line 1928, in _fetch_all
    self._result_cache = list(self._iterable_class(self))
                         ~~~~^^^^^^^^^^^^^^^^^^^^^^^^^^^^
  File "C:\Users\MSii\Desktop\Threat-Detection-and-Notification-Platform-by-Analyzing-Logs-of-Apache-and-MySQL-servers-\Venv\Lib\site-packages\django\db\models\query.py", line 91, in __iter__
    results = compiler.execute_sql(
        chunked_fetch=self.chunked_fetch, chunk_size=self.chunk_size
    )
  File "C:\Users\MSii\Desktop\Threat-Detection-and-Notification-Platform-by-Analyzing-Logs-of-Apache-and-MySQL-servers-\Venv\Lib\site-packages\django\db\models\sql\compiler.py", line 1574, in execute_sql
    cursor.execute(sql, params)
    ~~~~~~~~~~~~~~^^^^^^^^^^^^^
  File "C:\Users\MSii\Desktop\Threat-Detection-and-Notification-Platform-by-Analyzing-Logs-of-Apache-and-MySQL-servers-\Venv\Lib\site-packages\django\db\backends\utils.py", line 122, in execute
    return super().execute(sql, params)
           ~~~~~~~~~~~~~~~^^^^^^^^^^^^^
  File "C:\Users\MSii\Desktop\Threat-Detection-and-Notification-Platform-by-Analyzing-Logs-of-Apache-and-MySQL-servers-\Venv\Lib\site-packages\django\db\backends\utils.py", line 79, in execute
    return self._execute_with_wrappers(
           ~~~~~~~~~~~~~~~~~~~~~~~~~~~^
        sql, params, many=False, executor=self._execute
        ^^^^^^^^^^^^^^^^^^^^^^^^^^^^^^^^^^^^^^^^^^^^^^^
    )
    ^
  File "C:\Users\MSii\Desktop\Threat-Detection-and-Notification-Platform-by-Analyzing-Logs-of-Apache-and-MySQL-servers-\Venv\Lib\site-packages\django\db\backends\utils.py", line 92, in _execute_with_wrappers
    return executor(sql, params, many, context)
  File "C:\Users\MSii\Desktop\Threat-Detection-and-Notification-Platform-by-Analyzing-Logs-of-Apache-and-MySQL-servers-\Venv\Lib\site-packages\django\db\backends\utils.py", line 100, in _execute
    with self.db.wrap_database_errors:
         ^^^^^^^^^^^^^^^^^^^^^^^^^^^^
  File "C:\Users\MSii\Desktop\Threat-Detection-and-Notification-Platform-by-Analyzing-Logs-of-Apache-and-MySQL-servers-\Venv\Lib\site-packages\django\db\utils.py", line 91, in __exit__
    raise dj_exc_value.with_traceback(traceback) from exc_value
  File "C:\Users\MSii\Desktop\Threat-Detection-and-Notification-Platform-by-Analyzing-Logs-of-Apache-and-MySQL-servers-\Venv\Lib\site-packages\django\db\backends\utils.py", line 105, in _execute
    return self.cursor.execute(sql, params)
           ~~~~~~~~~~~~~~~~~~~^^^^^^^^^^^^^
  File "C:\Users\MSii\Desktop\Threat-Detection-and-Notification-Platform-by-Analyzing-Logs-of-Apache-and-MySQL-servers-\Venv\Lib\site-packages\django\db\backends\mysql\base.py", line 76, in execute
    return self.cursor.execute(query, args)
           ~~~~~~~~~~~~~~~~~~~^^^^^^^^^^^^^
  File "C:\Users\MSii\Desktop\Threat-Detection-and-Notification-Platform-by-Analyzing-Logs-of-Apache-and-MySQL-servers-\Venv\Lib\site-packages\MySQLdb\cursors.py", line 179, in execute
    res = self._query(mogrified_query)
  File "C:\Users\MSii\Desktop\Threat-Detection-and-Notification-Platform-by-Analyzing-Logs-of-Apache-and-MySQL-servers-\Venv\Lib\site-packages\MySQLdb\cursors.py", line 330, in _query
    db.query(q)
    ~~~~~~~~^^^
  File "C:\Users\MSii\Desktop\Threat-Detection-and-Notification-Platform-by-Analyzing-Logs-of-Apache-and-MySQL-servers-\Venv\Lib\site-packages\MySQLdb\connections.py", line 280, in query
    _mysql.connection.query(self, query)
    ~~~~~~~~~~~~~~~~~~~~~~~^^^^^^^^^^^^^
django.db.utils.OperationalError: (1054, "Unknown column 'ai_analytics_aireportfeedback.created_at' in 'SELECT'")
Error in report_detail: (1054, "Unknown column 'ai_analytics_aireportfeedback.created_at' in 'SELECT'")
Traceback (most recent call last):
  File "C:\Users\MSii\Desktop\Threat-Detection-and-Notification-Platform-by-Analyzing-Logs-of-Apache-and-MySQL-servers-\Venv\Lib\site-packages\django\db\backends\utils.py", line 105, in _execute
    return self.cursor.execute(sql, params)
           ~~~~~~~~~~~~~~~~~~~^^^^^^^^^^^^^
  File "C:\Users\MSii\Desktop\Threat-Detection-and-Notification-Platform-by-Analyzing-Logs-of-Apache-and-MySQL-servers-\Venv\Lib\site-packages\django\db\backends\mysql\base.py", line 76, in execute
    return self.cursor.execute(query, args)
           ~~~~~~~~~~~~~~~~~~~^^^^^^^^^^^^^
  File "C:\Users\MSii\Desktop\Threat-Detection-and-Notification-Platform-by-Analyzing-Logs-of-Apache-and-MySQL-servers-\Venv\Lib\site-packages\MySQLdb\cursors.py", line 179, in execute
    res = self._query(mogrified_query)
  File "C:\Users\MSii\Desktop\Threat-Detection-and-Notification-Platform-by-Analyzing-Logs-of-Apache-and-MySQL-servers-\Venv\Lib\site-packages\MySQLdb\cursors.py", line 330, in _query
    db.query(q)
    ~~~~~~~~^^^
  File "C:\Users\MSii\Desktop\Threat-Detection-and-Notification-Platform-by-Analyzing-Logs-of-Apache-and-MySQL-servers-\Venv\Lib\site-packages\MySQLdb\connections.py", line 280, in query
    _mysql.connection.query(self, query)
    ~~~~~~~~~~~~~~~~~~~~~~~^^^^^^^^^^^^^
MySQLdb.OperationalError: (1054, "Unknown column 'ai_analytics_aireportfeedback.created_at' in 'SELECT'")

The above exception was the direct cause of the following exception:

Traceback (most recent call last):
  File "C:\Users\MSii\Desktop\Threat-Detection-and-Notification-Platform-by-Analyzing-Logs-of-Apache-and-MySQL-servers-\ai_analytics\views.py", line 76, in report_detail
    user_feedback = AIReportFeedback.objects.filter(report=report, user=request.user).first()
  File "C:\Users\MSii\Desktop\Threat-Detection-and-Notification-Platform-by-Analyzing-Logs-of-Apache-and-MySQL-servers-\Venv\Lib\site-packages\django\db\models\query.py", line 1097, in first
    for obj in queryset[:1]:
               ~~~~~~~~^^^^
  File "C:\Users\MSii\Desktop\Threat-Detection-and-Notification-Platform-by-Analyzing-Logs-of-Apache-and-MySQL-servers-\Venv\Lib\site-packages\django\db\models\query.py", line 400, in __iter__
    self._fetch_all()
    ~~~~~~~~~~~~~~~^^
  File "C:\Users\MSii\Desktop\Threat-Detection-and-Notification-Platform-by-Analyzing-Logs-of-Apache-and-MySQL-servers-\Venv\Lib\site-packages\django\db\models\query.py", line 1928, in _fetch_all
    self._result_cache = list(self._iterable_class(self))
                         ~~~~^^^^^^^^^^^^^^^^^^^^^^^^^^^^
  File "C:\Users\MSii\Desktop\Threat-Detection-and-Notification-Platform-by-Analyzing-Logs-of-Apache-and-MySQL-servers-\Venv\Lib\site-packages\django\db\models\query.py", line 91, in __iter__
    results = compiler.execute_sql(
        chunked_fetch=self.chunked_fetch, chunk_size=self.chunk_size
    )
  File "C:\Users\MSii\Desktop\Threat-Detection-and-Notification-Platform-by-Analyzing-Logs-of-Apache-and-MySQL-servers-\Venv\Lib\site-packages\django\db\models\sql\compiler.py", line 1574, in execute_sql
    cursor.execute(sql, params)
    ~~~~~~~~~~~~~~^^^^^^^^^^^^^
  File "C:\Users\MSii\Desktop\Threat-Detection-and-Notification-Platform-by-Analyzing-Logs-of-Apache-and-MySQL-servers-\Venv\Lib\site-packages\django\db\backends\utils.py", line 122, in execute
    return super().execute(sql, params)
           ~~~~~~~~~~~~~~~^^^^^^^^^^^^^
  File "C:\Users\MSii\Desktop\Threat-Detection-and-Notification-Platform-by-Analyzing-Logs-of-Apache-and-MySQL-servers-\Venv\Lib\site-packages\django\db\backends\utils.py", line 79, in execute
    return self._execute_with_wrappers(
           ~~~~~~~~~~~~~~~~~~~~~~~~~~~^
        sql, params, many=False, executor=self._execute
        ^^^^^^^^^^^^^^^^^^^^^^^^^^^^^^^^^^^^^^^^^^^^^^^
    )
    ^
  File "C:\Users\MSii\Desktop\Threat-Detection-and-Notification-Platform-by-Analyzing-Logs-of-Apache-and-MySQL-servers-\Venv\Lib\site-packages\django\db\backends\utils.py", line 92, in _execute_with_wrappers
    return executor(sql, params, many, context)
  File "C:\Users\MSii\Desktop\Threat-Detection-and-Notification-Platform-by-Analyzing-Logs-of-Apache-and-MySQL-servers-\Venv\Lib\site-packages\django\db\backends\utils.py", line 100, in _execute
    with self.db.wrap_database_errors:
         ^^^^^^^^^^^^^^^^^^^^^^^^^^^^
  File "C:\Users\MSii\Desktop\Threat-Detection-and-Notification-Platform-by-Analyzing-Logs-of-Apache-and-MySQL-servers-\Venv\Lib\site-packages\django\db\utils.py", line 91, in __exit__
    raise dj_exc_value.with_traceback(traceback) from exc_value
  File "C:\Users\MSii\Desktop\Threat-Detection-and-Notification-Platform-by-Analyzing-Logs-of-Apache-and-MySQL-servers-\Venv\Lib\site-packages\django\db\backends\utils.py", line 105, in _execute
    return self.cursor.execute(sql, params)
           ~~~~~~~~~~~~~~~~~~~^^^^^^^^^^^^^
  File "C:\Users\MSii\Desktop\Threat-Detection-and-Notification-Platform-by-Analyzing-Logs-of-Apache-and-MySQL-servers-\Venv\Lib\site-packages\django\db\backends\mysql\base.py", line 76, in execute
    return self.cursor.execute(query, args)
           ~~~~~~~~~~~~~~~~~~~^^^^^^^^^^^^^
  File "C:\Users\MSii\Desktop\Threat-Detection-and-Notification-Platform-by-Analyzing-Logs-of-Apache-and-MySQL-servers-\Venv\Lib\site-packages\MySQLdb\cursors.py", line 179, in execute
    res = self._query(mogrified_query)
  File "C:\Users\MSii\Desktop\Threat-Detection-and-Notification-Platform-by-Analyzing-Logs-of-Apache-and-MySQL-servers-\Venv\Lib\site-packages\MySQLdb\cursors.py", line 330, in _query
    db.query(q)
    ~~~~~~~~^^^
  File "C:\Users\MSii\Desktop\Threat-Detection-and-Notification-Platform-by-Analyzing-Logs-of-Apache-and-MySQL-servers-\Venv\Lib\site-packages\MySQLdb\connections.py", line 280, in query
    _mysql.connection.query(self, query)
    ~~~~~~~~~~~~~~~~~~~~~~~^^^^^^^^^^^^^
django.db.utils.OperationalError: (1054, "Unknown column 'ai_analytics_aireportfeedback.created_at' in 'SELECT'")
Error in report_detail: (1054, "Unknown column 'ai_analytics_aireportfeedback.created_at' in 'SELECT'")
Traceback (most recent call last):
  File "C:\Users\MSii\Desktop\Threat-Detection-and-Notification-Platform-by-Analyzing-Logs-of-Apache-and-MySQL-servers-\Venv\Lib\site-packages\django\db\backends\utils.py", line 105, in _execute
    return self.cursor.execute(sql, params)
           ~~~~~~~~~~~~~~~~~~~^^^^^^^^^^^^^
  File "C:\Users\MSii\Desktop\Threat-Detection-and-Notification-Platform-by-Analyzing-Logs-of-Apache-and-MySQL-servers-\Venv\Lib\site-packages\django\db\backends\mysql\base.py", line 76, in execute
    return self.cursor.execute(query, args)
           ~~~~~~~~~~~~~~~~~~~^^^^^^^^^^^^^
  File "C:\Users\MSii\Desktop\Threat-Detection-and-Notification-Platform-by-Analyzing-Logs-of-Apache-and-MySQL-servers-\Venv\Lib\site-packages\MySQLdb\cursors.py", line 179, in execute
    res = self._query(mogrified_query)
  File "C:\Users\MSii\Desktop\Threat-Detection-and-Notification-Platform-by-Analyzing-Logs-of-Apache-and-MySQL-servers-\Venv\Lib\site-packages\MySQLdb\cursors.py", line 330, in _query
    db.query(q)
    ~~~~~~~~^^^
  File "C:\Users\MSii\Desktop\Threat-Detection-and-Notification-Platform-by-Analyzing-Logs-of-Apache-and-MySQL-servers-\Venv\Lib\site-packages\MySQLdb\connections.py", line 280, in query
    _mysql.connection.query(self, query)
    ~~~~~~~~~~~~~~~~~~~~~~~^^^^^^^^^^^^^
MySQLdb.OperationalError: (1054, "Unknown column 'ai_analytics_aireportfeedback.created_at' in 'SELECT'")

The above exception was the direct cause of the following exception:

Traceback (most recent call last):
  File "C:\Users\MSii\Desktop\Threat-Detection-and-Notification-Platform-by-Analyzing-Logs-of-Apache-and-MySQL-servers-\ai_analytics\views.py", line 76, in report_detail
    user_feedback = AIReportFeedback.objects.filter(report=report, user=request.user).first()
  File "C:\Users\MSii\Desktop\Threat-Detection-and-Notification-Platform-by-Analyzing-Logs-of-Apache-and-MySQL-servers-\Venv\Lib\site-packages\django\db\models\query.py", line 1097, in first
    for obj in queryset[:1]:
               ~~~~~~~~^^^^
  File "C:\Users\MSii\Desktop\Threat-Detection-and-Notification-Platform-by-Analyzing-Logs-of-Apache-and-MySQL-servers-\Venv\Lib\site-packages\django\db\models\query.py", line 400, in __iter__
    self._fetch_all()
    ~~~~~~~~~~~~~~~^^
  File "C:\Users\MSii\Desktop\Threat-Detection-and-Notification-Platform-by-Analyzing-Logs-of-Apache-and-MySQL-servers-\Venv\Lib\site-packages\django\db\models\query.py", line 1928, in _fetch_all
    self._result_cache = list(self._iterable_class(self))
                         ~~~~^^^^^^^^^^^^^^^^^^^^^^^^^^^^
  File "C:\Users\MSii\Desktop\Threat-Detection-and-Notification-Platform-by-Analyzing-Logs-of-Apache-and-MySQL-servers-\Venv\Lib\site-packages\django\db\models\query.py", line 91, in __iter__
    results = compiler.execute_sql(
        chunked_fetch=self.chunked_fetch, chunk_size=self.chunk_size
    )
  File "C:\Users\MSii\Desktop\Threat-Detection-and-Notification-Platform-by-Analyzing-Logs-of-Apache-and-MySQL-servers-\Venv\Lib\site-packages\django\db\models\sql\compiler.py", line 1574, in execute_sql
    cursor.execute(sql, params)
    ~~~~~~~~~~~~~~^^^^^^^^^^^^^
  File "C:\Users\MSii\Desktop\Threat-Detection-and-Notification-Platform-by-Analyzing-Logs-of-Apache-and-MySQL-servers-\Venv\Lib\site-packages\django\db\backends\utils.py", line 122, in execute
    return super().execute(sql, params)
           ~~~~~~~~~~~~~~~^^^^^^^^^^^^^
  File "C:\Users\MSii\Desktop\Threat-Detection-and-Notification-Platform-by-Analyzing-Logs-of-Apache-and-MySQL-servers-\Venv\Lib\site-packages\django\db\backends\utils.py", line 79, in execute
    return self._execute_with_wrappers(
           ~~~~~~~~~~~~~~~~~~~~~~~~~~~^
        sql, params, many=False, executor=self._execute
        ^^^^^^^^^^^^^^^^^^^^^^^^^^^^^^^^^^^^^^^^^^^^^^^
    )
    ^
  File "C:\Users\MSii\Desktop\Threat-Detection-and-Notification-Platform-by-Analyzing-Logs-of-Apache-and-MySQL-servers-\Venv\Lib\site-packages\django\db\backends\utils.py", line 92, in _execute_with_wrappers
    return executor(sql, params, many, context)
  File "C:\Users\MSii\Desktop\Threat-Detection-and-Notification-Platform-by-Analyzing-Logs-of-Apache-and-MySQL-servers-\Venv\Lib\site-packages\django\db\backends\utils.py", line 100, in _execute
    with self.db.wrap_database_errors:
         ^^^^^^^^^^^^^^^^^^^^^^^^^^^^
  File "C:\Users\MSii\Desktop\Threat-Detection-and-Notification-Platform-by-Analyzing-Logs-of-Apache-and-MySQL-servers-\Venv\Lib\site-packages\django\db\utils.py", line 91, in __exit__
    raise dj_exc_value.with_traceback(traceback) from exc_value
  File "C:\Users\MSii\Desktop\Threat-Detection-and-Notification-Platform-by-Analyzing-Logs-of-Apache-and-MySQL-servers-\Venv\Lib\site-packages\django\db\backends\utils.py", line 105, in _execute
    return self.cursor.execute(sql, params)
           ~~~~~~~~~~~~~~~~~~~^^^^^^^^^^^^^
  File "C:\Users\MSii\Desktop\Threat-Detection-and-Notification-Platform-by-Analyzing-Logs-of-Apache-and-MySQL-servers-\Venv\Lib\site-packages\django\db\backends\mysql\base.py", line 76, in execute
    return self.cursor.execute(query, args)
           ~~~~~~~~~~~~~~~~~~~^^^^^^^^^^^^^
  File "C:\Users\MSii\Desktop\Threat-Detection-and-Notification-Platform-by-Analyzing-Logs-of-Apache-and-MySQL-servers-\Venv\Lib\site-packages\MySQLdb\cursors.py", line 179, in execute
    res = self._query(mogrified_query)
  File "C:\Users\MSii\Desktop\Threat-Detection-and-Notification-Platform-by-Analyzing-Logs-of-Apache-and-MySQL-servers-\Venv\Lib\site-packages\MySQLdb\cursors.py", line 330, in _query
    db.query(q)
    ~~~~~~~~^^^
  File "C:\Users\MSii\Desktop\Threat-Detection-and-Notification-Platform-by-Analyzing-Logs-of-Apache-and-MySQL-servers-\Venv\Lib\site-packages\MySQLdb\connections.py", line 280, in query
    _mysql.connection.query(self, query)
    ~~~~~~~~~~~~~~~~~~~~~~~^^^^^^^^^^^^^
django.db.utils.OperationalError: (1054, "Unknown column 'ai_analytics_aireportfeedback.created_at' in 'SELECT'")
Error in submit_report_feedback: Invalid field name(s) for model AIReportFeedback: 'created_at'.
Traceback (most recent call last):
  File "C:\Users\MSii\Desktop\Threat-Detection-and-Notification-Platform-by-Analyzing-Logs-of-Apache-and-MySQL-servers-\Venv\Lib\site-packages\django\db\models\query.py", line 948, in get_or_create
    return self.get(**kwargs), False
           ~~~~~~~~^^^^^^^^^^
  File "C:\Users\MSii\Desktop\Threat-Detection-and-Notification-Platform-by-Analyzing-Logs-of-Apache-and-MySQL-servers-\Venv\Lib\site-packages\django\db\models\query.py", line 649, in get
    raise self.model.DoesNotExist(
        "%s matching query does not exist." % self.model._meta.object_name
    )
ai_analytics.models.AIReportFeedback.DoesNotExist: AIReportFeedback matching query does not exist.

During handling of the above exception, another exception occurred:

Traceback (most recent call last):
  File "C:\Users\MSii\Desktop\Threat-Detection-and-Notification-Platform-by-Analyzing-Logs-of-Apache-and-MySQL-servers-\ai_analytics\views.py", line 275, in submit_report_feedback
    feedback, created = AIReportFeedback.objects.update_or_create(
                        ~~~~~~~~~~~~~~~~~~~~~~~~~~~~~~~~~~~~~~~~~^
        report=report,
        ^^^^^^^^^^^^^^
    ...<5 lines>...
        }
        ^
    )
    ^
  File "C:\Users\MSii\Desktop\Threat-Detection-and-Notification-Platform-by-Analyzing-Logs-of-Apache-and-MySQL-servers-\Venv\Lib\site-packages\django\db\models\manager.py", line 87, in manager_method
    return getattr(self.get_queryset(), name)(*args, **kwargs)
           ~~~~~~~~~~~~~~~~~~~~~~~~~~~~~~~~~~^^^^^^^^^^^^^^^^^
  File "C:\Users\MSii\Desktop\Threat-Detection-and-Notification-Platform-by-Analyzing-Logs-of-Apache-and-MySQL-servers-\Venv\Lib\site-packages\django\db\models\query.py", line 986, in update_or_create
    obj, created = self.select_for_update().get_or_create(
                   ~~~~~~~~~~~~~~~~~~~~~~~~~~~~~~~~~~~~~~^
        create_defaults, **kwargs
        ^^^^^^^^^^^^^^^^^^^^^^^^^
    )
    ^
  File "C:\Users\MSii\Desktop\Threat-Detection-and-Notification-Platform-by-Analyzing-Logs-of-Apache-and-MySQL-servers-\Venv\Lib\site-packages\django\db\models\query.py", line 950, in get_or_create
    params = self._extract_model_params(defaults, **kwargs)
  File "C:\Users\MSii\Desktop\Threat-Detection-and-Notification-Platform-by-Analyzing-Logs-of-Apache-and-MySQL-servers-\Venv\Lib\site-packages\django\db\models\query.py", line 1039, in _extract_model_params
    raise exceptions.FieldError(
    ...<5 lines>...
    )
django.core.exceptions.FieldError: Invalid field name(s) for model AIReportFeedback: 'created_at'.
Internal Server Error: /ai/reports/1/feedback/
Error extracting data for report: name 'MysqlLogEntry' is not defined
Traceback (most recent call last):
  File "C:\Users\MSii\Desktop\Threat-Detection-and-Notification-Platform-by-Analyzing-Logs-of-Apache-and-MySQL-servers-\ai_analytics\services.py", line 374, in _extract_data_for_time_period
    mysql_logs = MysqlLogEntry.objects.filter(mysql_filter).order_by('-timestamp')[:100]
                 ^^^^^^^^^^^^^
NameError: name 'MysqlLogEntry' is not defined. Did you mean: 'MySQLLogEntry'?
